Workbook
Name _5面遮水: #REF!
Name _6面遮水: #REF!
Name _シート無: #REF!
Name ・・・: #REF!
Name a: #REF!
Name AAM: #REF!
Name ah: #REF!
Name AIX: #REF!
Name AJC: #REF!
Name AJG: #REF!
Name AMM: #REF!
Name b: #REF!
Name BS_1500歩掛: #REF!
Name BS_2000歩掛: #REF!
Name BS_2500歩掛: #REF!
Name buzai_kg: [2]mst製品質量!$D$3:$G$240
Name cellレッカー規格1: [2]【入力】概要!$J$35
Name cellレッカー規格2: [2]【入力】概要!$J$36
Name cellレッカー種類1: [2]【入力】概要!$F$35
Name cellレッカー種類2: [2]【入力】概要!$F$36
Name cellレッカー賃料txt: [2]mst_単価!$A$52
Name cell営業所: [2]【入力】概要!$AC$14
Name cell管理番号: [2]【入力】概要!$AC$13
Name cell軽油: [2]【入力】詳細!$C$74
Name cell県: #REF!
Name cell工事費: [2]【入力】概要!$T$7
Name cell高n: [2]数量計算書_組立図ツール連動用!$AL$99
Name cell高さ: [2]【入力】概要!$H$4
Name cell担当者: [2]【入力】概要!$AC$15
Name cell地域: [2]【入力】概要!$P$34
Name cell年度: [2]mst_労務!$A$1
Name cell余裕高: [2]【入力】概要!$AE$6
Name change: #REF!
Name Dept_list: #REF!
Name Dept_to_FA: #REF!
Name E: #REF!
Name I_1500歩掛: #REF!
Name I_2000歩掛: #REF!
Name I_2500歩掛: #REF!
Name inM3クラス: [2]【入力】標準組立図!$C$7
Name inふた幅: [2]【入力】標準組立図!$C$8
Name in県: [2]【入力】標準組立図!$C$5
Name in高さ: [2]【入力】標準組立図!$C$6
Name in製品重量: [2]【入力】標準組立図!$H$9
Name in製品単価: [2]【入力】標準組立図!$C$12
Name in余裕高: [2]【入力】標準組立図!$C$9
Name JTB担当: [3]DB!$F$2:$F$9
Name mst_Qfuta: '[2]参_ふた、端面D規格'!$B$23:$F$46
Name mst_Qtand: '[2]参_ふた、端面D規格'!$B$50:$G$91
Name NAME: #REF!
Name PIBO: #REF!
Name SH: #REF!
Name sw: [2]数量計算書_組立図ツール連動用!$AI$2
Name tblCOST00: [2]mst_FB000!$BA$4:$BA$108
Name tblCOST06: [2]mst_FB600!$BA$4:$BA$108
Name tblHP: [2]mst!$C$160:$D$175
Name tblHP呼び径: [2]mst!$B$160:$B$175
Name tblSTDID_見出00: [2]mst_FB000!$B$4:$AZ$108
Name tblSTDID_見出06: [2]mst_FB600!$B$4:$AZ$108
Name tblSTDID00: [2]mst_FB000!$A$4:$A$108

Sheet 【251001】アジア選手積算
M1: 契約現状０のため法的には確保０です。この数字に法的拘束力はありません | AG1: ホテル独自見積 | FP1: ホテル独自見積
I2: 契約現状０のため | AG2: 1/20シミュ（射撃が豊田Ver.） | FP2: 1/20シミュ（射撃が豊田Ver.）
AI3: 現状の平均額 | AK3: =ROUNDUP(SUM(AK50,AK56,AK85,AK99,AK101,AK109,AK117,AK119,AK129,AK131,AK133,AK145,AK149,AK151,AK155,AK89,AK127,[1]【251001】パラ選手積算!CL10,AK64)/19,0) -> 27337 | AM3: =ROUNDUP(SUM(AM50,AM56,AM85,AM99,AM101,AM109,AM117,AM119,AM129,AM131,AM133,AM145,AM149,AM151,AM155,AM89,AM127,[1]【251001】パラ選手積算!CN10,AM64)/19,0) -> 25503 | AO3: =ROUNDUP(SUM(AO50,AO56,AO85,AO89,AO99,AO101,AO109,AO117,AO119,AO129,AO131,AO133,AO145,AO149,AO151,AO155,[1]【251001】パラ選手積算!CP10,AO64)/18,0) -> 2455
AA4: 最新版 | AI4: 予算要求時の平均額 | AK4: 26106 | AM4: 24690 | AO4: 2373 | AW4: ｽｲｰﾄは除いてます | BV4: 2026/2/5時点資料 | DI4: 2/5時点資料 | DQ4: →これより右は数式なし | EK4: 予算要求時点資料 | FZ4: ｽｲｰﾄは除いてます | GW4: 7/25時点資料 | IJ4: 7/25時点資料
I5: この数字に法的拘束力はありません | AG5: 金額はホテルから見積もり取得済みのもの以外は上がる可能性があります | AZ5: １日あたり総額×差引日数 | BA5: １日あたり総額×差引日数 | FP5: 金額はホテルから見積もり取得済みのもの以外は上がる可能性があります | GC5: １日あたり総額×差引日数 | GD5: １日あたり総額×差引日数
AE6: 仮で入れてあります | AF6: 仮で入れてあります | AW6: ※除くスイートルーム | AZ6: 仮入力 | BA6: 仮入力 | DM6: 隠し計算用 | ES6: 45677 | ET6: 45672 | EU6: 45961 | FN6: 仮で入れてあります | FO6: 仮で入れてあります | FZ6: ※除くスイートルーム | GC6: 仮入力 | GD6: 仮入力 | IN6: 隠し計算用
B7: アジア競技大会における選手団宿泊施設想定 | AG7: 単位：円 | AJ7: 計算用 | AK7: ※黄色：仮置き。見積もりが来ているホテルの見積単価の平均値を他のホテルに反映 | AL7: 計算用 | AS7: 単位：円 | AT7: 単位：円 | AU7: 単位：円 | AV7: 単位：円 | AW7: 単位：円 | AX7: 単位：円 | AZ7: 単位：円 | BA7: 単位：円 | BB7: 6割 | BC7: 参考 | BD7: ６割 | BE7: これいる？ | BF7: ４割 | BG7: これいる？ | BH7: 3割 | DI7: 取り扱い注意 | FP7: 単位：円 | FV7: 単位：円 | FW7: 単位：円 | FX7: 単位：円 | FY7: 単位：円 | FZ7: 単位：円 | GA7: 単位：円 | GC7: 単位：円 | GD7: 単位：円 | GE7: けんしょー | GL7: けんしょー | IJ7: 取り扱い注意 | IR7: 1031財政見通し積算（12,600人の時点の配宿シミュレーション）
E8: 非表示 | G8: 非表示 | I8: 編集中 | L8: 非表示 | V8: 非表示※全棟貸切：企業契約や長期滞在者を除く貸切をイメージ | CR8: 開会式 | DG8: 閉会式 | EY8: 総長レク時非表示？ | HS8: 開会式 | IH8: 閉会式
B9: 所在地 | D9: 通し 番号 | E9: 施設 番号 | F9: 宿泊施設基本情報 | G9: 保有客室 | I9: 提供可能客室数 | K9: おためし 整合性管理 | L9: 最大 瞬間風速 | M9: ﾌｧﾝｸｼｮﾝ 保有数 | N9: 食事提供 難易度 | O9: 食事提供 主体想定 | P9: 朝食会場 座席数 | Q9: その他宿泊施設機能 | T9: 乗降場 | U9: 利用想定 | V9: 貸切 想定（※） | X9: 別紙 | AA9: 15,000人 | AE9: 変動有無 | AF9: 見積もり取得状況 | AG9: 一日あたり 客室総額 （税込） | AH9: 朝食単価 （素泊まり契約の場合は０） | AK9: 附属契約 | AM9: 附属契約 | AN9: 附属 | AO9: 附属契約 | AP9: 利用想定 客室数 | AQ9: 収容可能人数 | AR9: 平均宿泊人数 | AS9: 一人あたり 平均単価 （税込） | AT9: 1室あたり単価 （税込） | AU9: 1ベッドあたり単価 （税込） | AV9: 客室単価幅 最低 （税抜） | AW9: 客室単価幅 最高 （税抜） | AX9: 一日あたりﾌｧﾝｸｼｮﾝ総額 （税込） | AY9: ﾌｧﾝｸｼｮﾝ 利用想定数 | AZ9: 客室総計 （税込） | BA9: ﾌｧﾝｸｼｮﾝ 総計 （税込） | BB9: 附属契約 | BC9: 基本契約に含まれる朝食代 | BD9: 附属契約 | BF9: 附属契約 | BH9: 附属契約 | BI9: 入湯税or宿泊税 | BJ9: その他 | BK9: その他 | BL9: その他 | BM9: 想定 | BN9: テナントの数（ショップ含む） | BO9: キャンセルポリシーにより | BQ9: 7月末財政見通しとの | BT9: チェックイン | BU9: チェックアウト | BV9: 開始日 | BW9: 終了日 | BX9: 確保 泊数 | BY9: 46265 | BZ9: 46266 | CA9: 46267 | CB9: 46268 | CC9: 46269 | CD9: 46270 | CE9: 46271 | CF9: 46272 | CG9: 46273 | CH9: 46274 | CI9: 46275 | CJ9: 46276 | CK9: 46277 | CL9: 46278 | CM9: 46279 | CN9: 46280 | CO9: 46281 | CP9: 46282 | CQ9: 46283 | CR9: 46284 | CS9: 46285 | CT9: 46286 | CU9: 46287 | CV9: 46288 | CW9: 46289 | CX9: 46290 | CY9: 46291 | CZ9: 46292 | DA9: 46293 | DB9: 46294 | DC9: 46295 | DD9: 46296 | DE9: 46297 | DF9: 46298 | DG9: 46299 | DH9: 46300 | DI9: 46301 | DJ9: 46302 | DK9: 46303 | DQ9: 15,000人 | DU9: 一日あたり 客室総額 （税込） | DV9: 一日あたりﾌｧﾝｸｼｮﾝ総額 （税込） | DW9: 客室総計 （税込） | DX9: ﾌｧﾝｸｼｮﾝ 総計 （税込） | DY9: 附属契約 | DZ9: 附属契約 | EA9: 附属契約 | EB9: 附属契約 | EC9: 入湯税or宿泊税 | ED9: その他 | EE9: その他 | EF9: その他 | EG9: キャンセルポリシーにより | EK9: 開始日 | EL9: 終了日 | EM9: 確保 泊数 | EO9: 15,000人 | EW9: 競技会場 | EY9: 練習会場① | FB9: 練習会場② | FE9: 練習会場③ | FH9: 練習会場④ | FK9: 最大瞬間 風速時 予備ベッド数 | FL9: 予備率 | FM9: 区分 | FN9: 契約交渉状況 | FO9: 見積もり取得状況 | FP9: 一日あたり 客室総額 （税込） | FQ9: 朝食単価 （素泊まり契約の場合は０） | FR9: 4100との差額 | FS9: 利用想定 客室数 | FT9: 収容可能人数 | FU9: 平均宿泊人数 | FV9: 一人あたり 平均単価 （税込） | FW9: 1室あたり単価 （税込） | FX9: 1ベッドあたり単価 （税込） | FY9: 客室単価幅 最低 （税抜） | FZ9: 客室単価幅 最高 （税抜） | GA9: 一日あたりﾌｧﾝｸｼｮﾝ総額 （税込） | GB9: ﾌｧﾝｸｼｮﾝ 利用想定数 | GC9: 客室総計 （税込） | GD9: ﾌｧﾝｸｼｮﾝ 総計 （税込） | GE9: 客室総計 （税込） | GF9: ﾌｧﾝｸｼｮﾝ 総計 （税込） | GI9: アスリートミール差額の朝食加算 | GJ9: 入湯税or宿泊税 | GK9: その他 | GL9: その他 | GN9: その他 | GO9: その他 | GP9: 想定 | GQ9: テナントの数（ショップ含む） | GW9: 開始日 | GX9: 終了日 | GY9: 確保 泊数 | GZ9: 46265 | HA9: 46266 | HB9: 46267 | HC9: 46268 | HD9: 46269 | HE9: 46270 | HF9: 46271 | HG9: 46272 | HH9: 46273 | HI9: 46274 | HJ9: 46275 | HK9: 46276 | HL9: 46277 | HM9: 46278 | HN9: 46279 | HO9: 46280 | HP9: 46281 | HQ9: 46282 | HR9: 46283 | HS9: 46284 | HT9: 46285 | HU9: 46286 | HV9: 46287 | HW9: 46288 | HX9: 46289 | HY9: 46290 | HZ9: 46291 | IA9: 46292 | IB9: 46293 | IC9: 46294 | ID9: 46295 | IE9: 46296 | IF9: 46297 | IG9: 46298 | IH9: 46299 | II9: 46300 | IJ9: 46301 | IK9: 46302 | IL9: 46303 | IO9: 案1～3の記載 案1…あらゆるSH想定 案2・・・除外SH想定 案3・・・今あるもので決め打ち | IP9: 備考 ※除外SH・競技（＝確実に配宿されないことから確保期間に反映させなくてよいSH)などを記載 | IR9: 一日あたり 客室総額 （税込） | IS9: 利用想定 客室数 | IT9: 平均宿泊人数 | IU9: 一人当たり 平均単価 （税込） | IV9: 客室単価幅 最低 （税抜） | IW9: 客室単価幅 最高 （税抜） | IX9: 一日あたりﾌｧﾝｸｼｮﾝ総額 （税込） | IY9: ﾌｧﾝｸｼｮﾝ 利用想定数 | IZ9: 客室総計 （税込） | JA9: ﾌｧﾝｸｼｮﾝ 総計 （税込） | JB9: 食費 | JC9: その他 | JD9: 開始日 | JE9: 終了日 | JF9: 確保 泊数 | JG9: 新財政見通し（作成中）積算 | JO9: 46269 | JP9: 46270 | JQ9: 46271 | JR9: 46272 | JS9: 46273 | JT9: 46274 | JU9: 46275 | JV9: 46276 | JW9: 46277 | JX9: 46278 | JY9: 46279 | JZ9: 46280 | KA9: 46281 | KB9: 46282 | KC9: 46283 | KD9: 46284 | KE9: 46285 | KF9: 46286 | KG9: 46287 | KH9: 46288 | KI9: 46289 | KJ9: 46290 | KK9: 46291 | KL9: 46292 | KM9: 46293 | KN9: 46294 | KO9: 46295 | KP9: 46296 | KQ9: 46297 | KR9: 46298 | KS9: 46299 | KT9: 46300 | KU9: 46301 | KV9: 46302 | KW9: 46303
B10: エリア | C10: 市町村郡 | F10: 施設名 | G10: 総客室数 | H10: 収容可能人数 | I10: 客室数 | J10: 収容可能人数 | Q10: ジム | R10: サウナ | S10: コイン ランドリー | T10: 乗降場詳細 | U10: 15000 | X10: 1 | Y10: 2 | Z10: 3 | AA10: 配宿競技 | AB10: 会場 | AC10: 人数 | AD10: 施設別 人数 | AI10: 4100円との差額 | AK10: 受領見積単価 （通常） | AM10: 受領見積単価 （ハラルヴィーガン） | AN10: ハラル 支援 | AO10: 受領見積単価 （グラブ＆ゴー） | BB10: アスリートミール差額の朝食加算 | BD10: 通常食合計 | BE10: 予算との乖離 （通常食） | BF10: ハラルヴィーガン合計 | BG10: 予算との乖離 （ハラルヴィーガン） | BH10: グラブアンドゴー合計 | BJ10: 営業補償等 | BK10: クリーンベニュー 営業補償 自販機 | BL10: クリーンベニュー 営業補償 テナント | BM10: 自販機の数 | BO10: 返せなかった分 | BP10: 施設合計 | BQ10: 差額 | BR10: 経緯 | BS10: 1031有無 | BT10: 契約開始日 | BU10: 契約終了日 | BY10: 月 | BZ10: 火 | CA10: 水 | CB10: 木 | CC10: 金 | CD10: 土 | CE10: 日 | CF10: 月 | CG10: 火 | CH10: 水 | CI10: 木 | CJ10: 金 | CK10: 土 | CL10: 日 | CM10: 月 | CN10: 火 | CO10: 水 | CP10: 木 | CQ10: 金 | CR10: 土 | CS10: 日 | CT10: 月 | CU10: 火 | CV10: 水 | CW10: 木 | CX10: 金 | CY10: 土 | CZ10: 日 | DA10: 月 | DB10: 火 | DC10: 水 | DD10: 木 | DE10: 金 | DF10: 土 | DG10: 日 | DH10: 月 | DI10: 火 | DJ10: 水 | DK10: 木 | DM10: のべ宿泊 | DN10: 収入計算用 | DQ10: 配宿競技 | DR10: 会場 | DS10: 人数 | DT10: 施設別 人数 | DY10: アスリートミール差額の朝食加算 | DZ10: 通常食合計 | EA10: ハラルヴィーガン合計 | EB10: グラブアンドゴー合計 | ED10: 営業補償等 | EE10: クリーンベニュー 営業補償 自販機 | EF10: クリーンベニュー 営業補償 テナント | EG10: 返せなかった分 | EH10: 施設合計 | EI10: 契約開始日 | EJ10: 契約終了日 | EO10: 配宿競技 | EP10: 会場 | EQ10: 人数 | ER10: 施設別 人数 | ES10: 確認用 配宿人数 | ET10: 確認用 配宿人数 | EU10: 確認用 配宿人数 | EV10: 会場 | EW10: 距離 | EX10: 移動時間 | EY10: 練習会場① | EZ10: 距離 | FA10: 移動時間 | FB10: 練習会場② | FC10: 距離 | FD10: 移動時間 | FE10: 練習会場③ | FF10: 距離 | FG10: 移動時間 | FH10: 練習会場④ | FI10: 距離 | FJ10: 移動時間 | GK10: 営業補償等 | GL10: 営業補償等 | GN10: クリーンベニュー 営業補償 自販機 | GO10: クリーンベニュー 営業補償 テナント | GP10: 自販機の数 | GR10: 施設合計 | GS10: 積算金額確認用 | GT10: 1031有無 | GU10: 契約開始日 | GV10: 契約終了日 | GZ10: 月 | HA10: 火 | HB10: 水 | HC10: 木 | HD10: 金 | HE10: 土 | HF10: 日 | HG10: 月 | HH10: 火 | HI10: 水 | HJ10: 木 | HK10: 金 | HL10: 土 | HM10: 日 | HN10: 月 | HO10: 火 | HP10: 水 | HQ10: 木 | HR10: 金 | HS10: 土 | HT10: 日 | HU10: 月 | HV10: 火 | HW10: 水 | HX10: 木 | HY10: 金 | HZ10: 土 | IA10: 日 | IB10: 月 | IC10: 火 | ID10: 水 | IE10: 木 | IF10: 金 | IG10: 土 | IH10: 日 | II10: 月 | IJ10: 火 | IK10: 水 | IL10: 木 | IN10: のべ宿泊 | JC10: 営業補償等 | JG10: 客室総額 （一日あたり） | JH10: ファンクション総額 （1日あたり） | JO10: 金 | JP10: 土 | JQ10: 日 | JR10: 月 | JS10: 火 | JT10: 水 | JU10: 木 | JV10: 金 | JW10: 土 | JX10: 日 | JY10: 月 | JZ10: 火 | KA10: 水 | KB10: 木 | KC10: 金 | KD10: 土 | KE10: 日 | KF10: 月 | KG10: 火 | KH10: 水 | KI10: 木 | KJ10: 金 | KK10: 土 | KL10: 日 | KM10: 月 | KN10: 火 | KO10: 水 | KP10: 木 | KQ10: 金 | KR10: 土 | KS10: 日 | KT10: 月 | KU10: 火 | KV10: 水 | KW10: 木 | KY10: のべ宿泊
B11: 名古屋 | C11: 金城ふ頭 | D11: 1 | F11: ホテルシップ | G11: 1500 | H11: 3700 | I11: 1500 | J11: 3000 | K11: #N/A | L11: 3658 | M11: 調査中 | N11: 調査中 | O11: 宿泊施設 | P11: 調査中 | Q11: ○ | R11: ○ | S11: － | T11: 岸壁整備 | U11: ○ | V11: 全棟 | AA11: ハンドボール（男子） | AB11: 稲沢市 | AC11: 288 | AD11: =SUM(AC11:AC35) -> 4654 | AE11: 有 | AG11: =FP11 -> 0 | AH11: =FQ11 -> 0 | AI11: =FR11 -> 0 | AP11: =FS11 -> 0 | AQ11: =FT11 -> 0 | AR11: =FU11 -> 2782.6316 | AS11: ー | AT11: ー | AU11: ー | AV11: 26000 | AW11: 48000 | AX11: =GA11 -> 0 | AY11: =GB11 -> 0 | AZ11: =GC11 -> 0 | BA11: =GD11 -> 0 | BB11: =AI11*DM11 -> 0 | BC11: =AH11*DM11 -> 0 | BD11: =AK11*DM11*0.6 -> 0 | BF11: =AM11*DM11*0.4 -> 0 | BI11: =GJ11 -> 0 | BJ11: =GK11 -> 0 | BK11: =BM11*5000*BX11 -> 0 | BL11: =1800000*BN11*BX11 -> 0 | BM11: =GP11 -> 0 | BN11: =GQ11 -> 0 | BP11: =SUM(AZ11,BA11,BI11,BO11) -> 0 | BQ11: =BP11-GR11 -> 0 | BV11: =IFERROR(INDEX($BY$9:$DH$9, MATCH("準備", BY11:DK11, 0)), "") -> 46280 | BW11: {=IF(COUNTIF(BY11:DK11,"*撤去*")=0,"",INDEX(BY$9:DK$9,1,MAX(IF(CC11:DK11="撤去",COLUMN(CC11:DK11)-COLUMN(BY11)+1))))} -> 46301 | BX11: =BW11-BV11 -> 21 | BY11: 0 | BZ11: 0 | CA11: 0 | CB11: 0 | CC11: 0 | CD11: 0 | CE11: 0 | CF11: 0 | CG11: 0 | CH11: 0 | CI11: 0 | CJ11: 0 | CK11: 0 | CL11: 0 | CM11: 0 | CN11: 準備 | CO11: 1597 | CP11: 2223 | CQ11: 2327 | CR11: 2327 | CS11: 2587 | CT11: 2587 | CU11: 2920 | CV11: 3181 | CW11: 3380 | CX11: 3380 | CY11: 3447 | CZ11: 3632 | DA11: 3116 | DB11: 2956 | DC11: 2956 | DD11: 2337 | DE11: 2337 | DF11: 2337 | DG11: 2233 | DH11: 126 | DI11: 撤去 | DJ11: 0 | DK11: 0 | DM11: {=SUM(IF(ISNUMBER($BY11:$DK11),$BY11:$DK11, 0))} -> 51986 | EO11: ハンドボール（男子） | EP11: 稲沢市 | EQ11: 288 | ER11: 4725 | ES11: #N/A | ET11: #N/A | EU11: #N/A | EV11: 豊田合成記念体育館［エントリオ］ | EW11: 32.3 | EX11: 33 | EY11: 名古屋市名東スポーツセンター | EZ11: 27 | FA11: 31 | FB11: 名古屋市中村スポーツセンター | FC11: 23.7 | FD11: 29 | FE11: 稲沢市総合体育館 | FF11: 29.9 | FG11: 37 | FH11: 中部大学 | FI11: 42.8 | FJ11: 38 | FK11: 140 | FL11: 0.037837838 | FM11: ホテルシップ 合計 | FU11: 2782.6316 | GW11: 46280 | GX11: 46301 | GY11: 21 | GZ11: 0 | HA11: 0 | HB11: 0 | HC11: 0 | HD11: 0 | HE11: 0 | HF11: 0 | HG11: 0 | HH11: 0 | HI11: 0 | HJ11: 0 | HK11: 0 | HL11: 0 | HM11: 0 | HN11: 0 | HO11: 準備 | HP11: 1597 | HQ11: 2223 | HR11: 2327 | HS11: 2327 | HT11: 2587 | HU11: 2632 | HV11: 2965 | HW11: 3252 | HX11: 3451 | HY11: 3451 | HZ11: 3518 | IA11: 3658 | IB11: 3142 | IC11: 2982 | ID11: 2956 | IE11: 2625 | IF11: 2337 | IG11: 2337 | IH11: 2233 | II11: 270 | IJ11: 撤去 | IK11: 0 | IL11: 0 | IN11: {=SUM(IF(ISNUMBER($HD11:$IL11),$HD11:$IL11, 0))} -> 52870 | KY11: {=SUM(IF(ISNUMBER($HD11:$IL11),$HD11:$IL11, 0))} -> 52870
G12: 0 | H12: 0 | I12: 0 | J12: 0 | L12: 0 | M12: 0 | N12: 0 | O12: 0 | P12: 0 | Q12: 0 | R12: 0 | S12: 0 | AA12: アーチェリー | AB12: 岡崎市 | AC12: 333 | EO12: アーチェリー | EP12: 岡崎市 | EQ12: 333 | EV12: 岡崎中央総合公園多目的広場 | EW12: 47 | EX12: 39 | EY12: 競技会場に設置 | EZ12: 47 | FA12: 39 | FB12: ー | FE12: ー | FH12: ー
G13: 0 | H13: 0 | I13: 0 | J13: 0 | L13: 0 | M13: 0 | N13: 0 | O13: 0 | P13: 0 | Q13: 0 | R13: 0 | S13: 0 | AA13: 3x3 バスケットボール（男子） | AB13: 名古屋市 | AC13: 96 | EO13: 3x3 バスケットボール（男子） | EP13: 名古屋市 | EQ13: 96 | EV13: 金城ふ頭駅前特設コート | EW13: 1 | EX13: 2 | EY13: 競技会場に設置 | EZ13: 1 | FA13: 2 | FB13: ー | FE13: ー | FH13: ー
G14: 0 | H14: 0 | I14: 0 | J14: 0 | L14: 0 | M14: 0 | N14: 0 | O14: 0 | P14: 0 | Q14: 0 | R14: 0 | S14: 0 | AA14: 3x3 バスケットボール（女子） | AB14: 名古屋市 | AC14: 96 | EO14: 3x3 バスケットボール（女子） | EP14: 名古屋市 | EQ14: 96 | EV14: 金城ふ頭駅前特設コート | EW14: 1 | EX14: 2 | EY14: 競技会場に設置 | EZ14: 1 | FA14: 2 | FB14: ー | FE14: ー | FH14: ー
G15: 0 | H15: 0 | I15: 0 | J15: 0 | L15: 0 | M15: 0 | N15: 0 | O15: 0 | P15: 0 | Q15: 0 | R15: 0 | S15: 0 | AA15: カヌー・カヤック（スプリント） | AB15: みよし市 | AC15: 260 | EO15: カヌー・カヤック（スプリント） | EP15: みよし市 | EQ15: 260 | EV15: 三好池 | EW15: 31 | EX15: 39 | EY15: 競技会場に設置 | EZ15: 31 | FA15: 39 | FB15: ー | FE15: ー | FH15: ー
G16: 0 | H16: 0 | I16: 0 | J16: 0 | L16: 0 | M16: 0 | N16: 0 | O16: 0 | P16: 0 | Q16: 0 | R16: 0 | S16: 0 | EO16: 自転車競技（マウンテンバイク） | EP16: 名古屋市 | EQ16: 45 | EV16: 小幡緑地 | EW16: 33 | EX16: 28 | EY16: 競技会場に設置 | EZ16: 33 | FA16: 28 | FB16: ー | FE16: ー | FH16: ー
G17: 0 | H17: 0 | I17: 0 | J17: 0 | L17: 0 | M17: 0 | N17: 0 | O17: 0 | P17: 0 | Q17: 0 | R17: 0 | S17: 0 | EO17: 自転車競技（BMXレース） | EP17: 名古屋市 | EQ17: 26 | EV17: 名古屋市競輪場BMXレースコース | EW17: 24 | EX17: 28 | EY17: 競技会場に設置 | EZ17: 24 | FA17: 28 | FB17: ー | FE17: ー | FH17: ー
I18: 0 | J18: 0 | L18: 0 | AA18: 体操 | AB18: 名古屋市 | AC18: 210 | EO18: 体操 | EP18: 名古屋市 | EQ18: 210 | EV18: 名古屋市総合体育館［レインボーホール］ | EW18: 14 | EX18: 23 | EY18: ポートメッセなごや第二展示館 | EZ18: 0.6 | FA18: 2 | FB18: ー | FE18: ー | FH18: ー
G19: 0 | H19: 0 | I19: 0 | J19: 0 | L19: 0 | M19: 0 | N19: 0 | O19: 0 | P19: 0 | Q19: 0 | R19: 0 | S19: 0 | AA19: 新体操 | AB19: 名古屋市 | AC19: 126 | EO19: 新体操 | EP19: 名古屋市 | EQ19: 126 | EV19: 名古屋市総合体育館［レインボーホール］ | EW19: 14 | EX19: 23 | EY19: ポートメッセなごや第二展示館 | EZ19: 0.6 | FA19: 2 | FB19: ー | FE19: ー | FH19: ー
I20: 0 | J20: 0 | L20: 0 | AA20: トランポリン | AB20: 名古屋市 | AC20: 26 | EO20: トランポリン | EP20: 名古屋市 | EQ20: 26 | EV20: 名古屋市総合体育館［レインボーホール］ | EW20: 14 | EX20: 23 | EY20: ポートメッセなごや第二展示館 | EZ20: 0.6 | FA20: 2 | FB20: ー | FE20: ー | FH20: ー
AA21: 柔道 | AB21: 名古屋市 | AC21: 327 | EO21: 柔道 | EP21: 名古屋市 | EQ21: 327 | EV21: 愛知国際アリーナ | EW21: 25 | EX21: 28 | EY21: 愛知県体育館or露橋スポーツセンター | EZ21: 24.4 | FA21: 30 | FB21: ー | FE21: ー | FH21: ー
AA22: カバディ（男子） | AB22: 東海市 | AC22: 180 | EO22: カバディ（男子） | EP22: 東海市 | EQ22: 180 | EV22: 東海市民体育館 | EW22: 12 | EX22: 15 | EY22: 知多市民体育館 | EZ22: 14.7 | FA22: 20 | FB22: ー | FE22: ー | FH22: ー
AA23: カバディ（女子） | AB23: 東海市 | AC23: 144 | EO23: カバディ（女子） | EP23: 東海市 | EQ23: 144 | EV23: 東海市民体育館 | EW23: 12 | EX23: 15 | EY23: 知多市民体育館 | EZ23: 14.7 | FA23: 20 | FB23: ー | FE23: ー | FH23: ー
AA24: クラッシュ | AB24: 名古屋市 | AC24: 119 | EO24: クラッシュ | EP24: 名古屋市 | EQ24: 119 | EV24: 愛知県武道館 | EW24: 11 | EX24: 19 | EY24: 甚目寺総合体育館or露橋スポーツセンター | EZ24: 23.1 | FA24: 23 | FB24: ー | FE24: ー | FH24: ー
G25: 0 | H25: 0 | I25: 0 | J25: 0 | L25: 0 | M25: 0 | N25: 0 | O25: 0 | P25: 0 | Q25: 0 | R25: 0 | S25: 0 | AA25: ローイング | AB25: 海津市/愛西市 | AC25: 336 | EO25: ローイング | EP25: 海津市 | EQ25: 336 | EV25: 長良川国際レガッタコース | EW25: 31 | EX25: 38 | EY25: 競技会場に設置 | EZ25: 31 | FA25: 38 | FB25: ー | FE25: ー | FH25: ー
G26: 0 | H26: 0 | I26: 0 | J26: 0 | L26: 0 | M26: 0 | N26: 0 | O26: 0 | P26: 0 | Q26: 0 | R26: 0 | S26: 0 | AA26: ラグビー（男子） | AB26: 名古屋市 | AC26: 216 | EO26: ラグビー（男子） | EP26: 名古屋市 | EQ26: 216 | EV26: 名古屋市瑞穂公園ラグビー場 | EW26: 22 | EX26: 25 | EY26: 口論義運動公園サッカー場 | EZ26: 31.8 | FA26: 37 | FB26: 朝宮公園陸上競技場 | FC26: 38.5 | FD26: 43 | FE26: 名城大学日進グラウンド | FF26: 38 | FG26: 40 | FH26: 愛知学院大学グラウンド | FI26: 32.3 | FJ26: 41
G27: 0 | H27: 0 | I27: 0 | J27: 0 | L27: 0 | M27: 0 | N27: 0 | O27: 0 | P27: 0 | Q27: 0 | R27: 0 | S27: 0 | AA27: ラグビー（女子） | AB27: 名古屋市 | AC27: 144 | EO27: ラグビー（女子） | EP27: 名古屋市 | EQ27: 144 | EV27: 名古屋市瑞穂公園ラグビー場 | EW27: 22 | EX27: 25 | EY27: 口論義運動公園サッカー場 | EZ27: 31.2 | FA27: 37 | FB27: 朝宮公園陸上競技場 | FC27: 38.5 | FD27: 43 | FE27: 名城大学日進グラウンド | FF27: 38 | FG27: 40 | FH27: 愛知学院大学グラウンド | FI27: 32.3 | FJ27: 41
I28: 0 | J28: 0 | L28: 0 | AA28: セパタクロー | AB28: 名古屋市 | AC28: 311 | EO28: セパタクロー | EP28: 名古屋市 | EQ28: 311 | EV28: 名古屋市瑞穂公園体育館 | EW28: 24 | EX28: 29 | EY28: 北名古屋市健康ドーム | EZ28: 29.7 | FA28: 31 | FB28: ー | FE28: ー | FH28: ー
I29: 0 | J29: 0 | L29: 0 | AA29: スポーツクライミング | AB29: 名古屋市 | AC29: 144 | EO29: スポーツクライミング | EP29: 名古屋市 | EQ29: 144 | EV29: 名古屋市国際展示場［ポートメッセなごや］ | EW29: 1 | EX29: 2 | EY29: 競技会場に設置 | EZ29: 1 | FA29: 2 | FB29: ー | FE29: ー | FH29: ー
I30: 0 | J30: 0 | L30: 0 | AA30: スカッシュ | AB30: 名古屋市 | AC30: 104 | EO30: スカッシュ | EP30: 名古屋市 | EQ30: 104 | EV30: 名古屋市金城ふ頭アリーナ | EW30: 1 | EX30: 2 | EY30: 競技会場に設置 | EZ30: 1 | FA30: 2 | FB30: ー | FE30: ー | FH30: ー
I31: 0 | J31: 0 | L31: 0 | AA31: テニス | AB31: 名古屋市 | AC31: 261 | EO31: テニス | EP31: 名古屋市 | EQ31: 261 | EV31: 名古屋市東山公園テニスセンター | EW31: 26 | EX31: 28 | EY31: 競技会場に設置 | EZ31: 26 | FA31: 28 | FB31: ー | FE31: ー | FH31: ー
G32: 0 | H32: 0 | I32: 0 | J32: 0 | L32: 0 | M32: 0 | N32: 0 | O32: 0 | P32: 0 | Q32: 0 | R32: 0 | S32: 0 | AA32: ウェイトリフティング | AB32: 名古屋市 | AC32: 212 | EO32: ウェイトリフティング | EP32: 名古屋市 | EQ32: 212 | EV32: 名古屋市中小企業振興会館 | EW32: 28 | EX32: 26 | EY32: 競技会場に設置 | EZ32: 28 | FA32: 26 | FB32: ー | FE32: ー | FH32: ー
G33: 0 | H33: 0 | I33: 0 | J33: 0 | L33: 0 | M33: 0 | N33: 0 | O33: 0 | P33: 0 | Q33: 0 | R33: 0 | S33: 0 | AA33: レスリング | AB33: 名古屋市 | AC33: 371 | EO33: レスリング | EP33: 名古屋市 | EQ33: 371 | EV33: 稲永スポーツセンター | EW33: 5 | EX33: 8 | EY33: 愛知県体育館 | EZ33: 24.4 | FA33: 30 | FB33: ー | FE33: ー | FH33: ー
G34: 0 | H34: 0 | I34: 0 | J34: 0 | L34: 0 | M34: 0 | N34: 0 | O34: 0 | P34: 0 | Q34: 0 | R34: 0 | S34: 0 | AA34: 武術太極拳 | AB34: 名古屋市 | AC34: 260 | EO34: 武術太極拳 | EP34: 名古屋市 | EQ34: 260 | EV34: 愛知県武道館 | EW34: 11 | EX34: 19 | EY34: 親水公園総合体育館 | EZ34: 25.9 | FA34: 35 | FB34: ー | FE34: ー | FH34: ー
G35: 0 | H35: 0 | I35: 0 | J35: 0 | L35: 0 | M35: 0 | N35: 0 | O35: 0 | P35: 0 | Q35: 0 | R35: 0 | S35: 0 | AA35: 総合格闘技 | AB35: 名古屋市 | AC35: 90 | BY35: あまり | BZ35: 部屋 | CN35: 0 | CO35: 780 | CP35: 500 | CQ35: 460 | CR35: 460 | CS35: 340 | CT35: 340 | CU35: 190 | CV35: 80 | CW35: 0 | CX35: 0 | CY35: 0 | CZ35: 0 | DA35: 110 | DB35: 180 | DC35: 180 | DD35: 450 | DE35: 450 | DF35: 450 | DG35: 500 | DH35: 1370 | DI35: 0 | EO35: 総合格闘技 | EP35: 知多市 | EQ35: 90 | EV35: 新舞子マリンパーク | EW35: 20.2 | EX35: 23 | EY35: 南陽プール | EZ35: 9 | FA35: 15 | FB35: ー | FE35: ー | FH35: ー
C36: ガーデンふ頭 | D36: 2 | F36: 移動式宿泊施設 | H36: 1300 | J36: 1600 | K36: #N/A | L36: 1682 | M36: 調査中 | N36: 調査中 | O36: 0 | P36: 調査中 | Q36: 調査中 | R36: 調査中 | S36: 調査中 | T36: 調査中 | U36: ○ | V36: 全棟 | AA36: 水球（女子） | AB36: 名古屋市 | AC36: 135 | AD36: =SUM(AC36:AC49) -> 2530 | AE36: 有 | AG36: =FP36 -> 0 | AH36: =FQ36 -> 0 | AI36: =FR36 -> 0 | AP36: =FS36 -> 0 | AQ36: =FT36 -> 0 | AR36: =FU36 -> 1050.8857 | AS36: ー | AT36: ー | AU36: ー | AV36: 26000 | AW36: 48000 | AX36: =GA36 -> 0 | AY36: =GB36 -> 0 | AZ36: =GC36 -> 0 | BA36: =GD36 -> 0 | BB36: =AI36*DM36 -> 0 | BC36: =AH36*DM36 -> 0 | BD36: =AK36*DM36*0.6 -> 0 | BF36: =AM36*DM36*0.4 -> 0 | BI36: =GJ36 -> 0 | BJ36: =GK36 -> 0 | BK36: =BM36*5000*BX36 -> 0 | BL36: =1800000*BN36*BX36 -> 0 | BM36: =GP36 -> 0 | BN36: =GQ36 -> 0 | BP36: =SUM(AZ36,BA36,BI36,BO36) -> 0 | BQ36: =BP36-GR36 -> 0 | BV36: =IFERROR(INDEX($BY$9:$DH$9, MATCH("準備", BY36:DK36, 0)), "") -> 46265 | BW36: {=IF(COUNTIF(BY36:DK36,"*撤去*")=0,"",INDEX(BY$9:DK$9,1,MAX(IF(CC36:DK36="撤去",COLUMN(CC36:DK36)-COLUMN(BY36)+1))))} -> 46302 | BX36: =BW36-BV36 -> 37 | BY36: 準備 | BZ36: 準備 | CA36: 300 | CB36: 300 | CC36: 300 | CD36: 300 | CE36: 300 | CF36: 732 | CG36: 732 | CH36: 732 | CI36: 732 | CJ36: 876 | CK36: 1020 | CL36: 1416 | CM36: 1416 | CN36: 1416 | CO36: 1551 | CP36: 1551 | CQ36: 1551 | CR36: 1551 | CS36: 1551 | CT36: 1776 | CU36: 1668 | CV36: 1920 | CW36: 1658 | CX36: 1658 | CY36: 1523 | CZ36: 1442 | DA36: 1270 | DB36: 1234 | DC36: 1208 | DD36: 1208 | DE36: 1208 | DF36: 1028 | DG36: 1028 | DH36: 300 | DI36: 300 | DJ36: 撤去 | DK36: 0 | DM36: {=SUM(IF(ISNUMBER($BY36:$DK36),$BY36:$DK36, 0))} -> 38756 | EO36: 水球（女子） | EP36: 名古屋市 | EQ36: 135 | ER36: 2410 | ES36: #N/A | ET36: #N/A | EU36: #N/A | EV36: 名古屋市総合体育館［レインボープール］ | EW36: 6 | EX36: 15 | EY36: 口論義運動公園プール | EZ36: 30.5 | FA36: 44 | FB36: 春日井市温水プール | FC36: 27.5 | FD36: 35 | FE36: ー | FH36: ー | FK36: -476 | FL36: -0.36615385 | FM36: 移動式宿泊施設 合計 | FU36: 1050.8857 | GW36: 46265 | GX36: 46302 | GY36: 37 | GZ36: 準備 | HA36: 準備 | HB36: 300 | HC36: 300 | HD36: 300 | HE36: 300 | HF36: 300 | HG36: 732 | HH36: 732 | HI36: 732 | HJ36: 876 | HK36: 1020 | HL36: 1020 | HM36: 1416 | HN36: 1416 | HO36: 1682 | HP36: 1682 | HQ36: 1682 | HR36: 1682 | HS36: 1682 | HT36: 1682 | HU36: 1610 | HV36: 1430 | HW36: 1358 | HX36: 1538 | HY36: 1407 | HZ36: 1371 | IA36: 1335 | IB36: 1028 | IC36: 1028 | ID36: 1028 | IE36: 1028 | IF36: 1028 | IG36: 1028 | IH36: 1028 | II36: 300 | IJ36: 300 | IK36: 撤去 | IL36: 0 | IN36: {=SUM(IF(ISNUMBER($HD36:$IL36),$HD36:$IL36, 0))} -> 36781 | KY36: {=SUM(IF(ISNUMBER($HD36:$IL36),$HD36:$IL36, 0))} -> 36781
I37: 0 | J37: 0 | L37: 0 | AA37: 水球（男子） | AB37: 名古屋市 | AC37: 180 | EO37: 水球（男子） | EP37: 名古屋市 | EQ37: 180 | EV37: 名古屋市総合体育館［レインボープール］ | EW37: 37.6 | EX37: 40 | EY37: 口論義運動公園プール | EZ37: 38 | FA37: 40 | FB37: 春日井市温水プール | FE37: ー | FH37: ー
I38: 0 | J38: 0 | L38: 0 | AA38: バスケットボール（５×５／男子） | AB38: 名古屋市 | AC38: 216 | EO38: バスケットボール（５×５／男子） | EP38: 名古屋市 | EQ38: 216 | EV38: 愛知県新体育館［愛知国際アリーナ］ | EW38: 13 | EX38: 24 | EY38: ウィングアリーナ刈谷 | EZ38: 22 | FA38: 31 | FB38: 知立市福祉体育館 | FC38: 22 | FD38: 30 | FE38: ー | FH38: ー
AA39: バスケットボール（５×５／女子） | AB39: 名古屋市 | AC39: 216 | EO39: バスケットボール（５×５／女子） | EP39: 名古屋市 | EQ39: 216 | EV39: 愛知県新体育館［愛知国際アリーナ］ | EW39: 13 | EX39: 24 | EY39: ウィングアリーナ刈谷 | EZ39: 22 | FA39: 31 | FB39: 知立市福祉体育館 | FC39: 22 | FD39: 30 | FE39: ー | FH39: ー
I40: 0 | J40: 0 | L40: 0 | AA40: サッカー（男子／女子／港） | AB40: 名古屋市 | AC40: 288 | EO40: サッカー（男子／女子／港） | EP40: 名古屋市 | EQ40: 288 | EV40: 名古屋市港サッカー場 | EW40: 8 | EX40: 16 | EY40: 東員町スポーツ公園陸上競技場（三重） | EZ40: 38.8 | FA40: 41 | FB40: 半田陸上競技場（愛知） | FC40: 29.7 | FD40: 35 | FE40: 阿久比陸上競技場（愛知） | FF40: 25.4 | FG40: 34 | FH40: ー
...
