Workbook
Name _5面遮水: #REF!
Name _5面遮水: #REF!
Name _5面遮水: #REF!
Name _5面遮水: #REF!
Name _5面遮水: '債務負担行為積算 (数式)'!#REF!
Name _5面遮水: '債務負担行為積算 (全部盛り) '!#REF!
Name _5面遮水: #REF!
Name _6面遮水: #REF!
Name _6面遮水: #REF!
Name _6面遮水: #REF!
Name _6面遮水: #REF!
Name _6面遮水: '債務負担行為積算 (数式)'!#REF!
Name _6面遮水: '債務負担行為積算 (全部盛り) '!#REF!
Name _6面遮水: #REF!
Name _シート無: #REF!
Name _シート無: #REF!
Name _シート無: #REF!
Name _シート無: #REF!
Name _シート無: '債務負担行為積算 (数式)'!#REF!
Name _シート無: '債務負担行為積算 (全部盛り) '!#REF!
Name _シート無: #REF!
Name ・・・: #REF!
Name ・・・: #REF!
Name a: #REF!
Name a: [1]会場形態!$A$2:$A$6
Name a: [1]会場形態!$A$2:$A$6
Name a: #REF!
Name a: #REF!
Name a: #REF!
Name a: '債務負担行為積算 (数式)'!#REF!
Name a: '債務負担行為積算 (全部盛り) '!#REF!
Name a: #REF!
Name AAM: #REF!
Name AAM: #REF!
Name AAM: #REF!
Name AAM: '債務負担行為積算 (数式)'!#REF!
Name AAM: '債務負担行為積算 (全部盛り) '!#REF!
Name AAM: #REF!
Name ah: #REF!
Name ah: #REF!
Name ah: #REF!
Name ah: '債務負担行為積算 (数式)'!#REF!
Name ah: '債務負担行為積算 (全部盛り) '!#REF!
Name ah: #REF!
Name AIX: #REF!
Name AIX: #REF!
Name AIX: #REF!
Name AIX: '債務負担行為積算 (数式)'!#REF!
Name AIX: '債務負担行為積算 (全部盛り) '!#REF!
Name AIX: #REF!
Name AJC: #REF!
Name AJC: #REF!
Name AJC: #REF!
Name AJC: '債務負担行為積算 (数式)'!#REF!
Name AJC: '債務負担行為積算 (全部盛り) '!#REF!
Name AJC: #REF!
Name AJG: #REF!
Name AJG: #REF!
Name AJG: #REF!
Name AJG: '債務負担行為積算 (数式)'!#REF!

Sheet Sheet1
B1: 施設番号 | C1: 施設名 | D1: 住所 | E1: 市町村
B2: 4 | C2: =VLOOKUP(B2,#REF!,2,FALSE) -> #REF! | D2: =VLOOKUP(B2,#REF!,3,FALSE) -> #REF! | E2: 一宮市
B3: 8 | C3: =VLOOKUP(B3,#REF!,2,FALSE) -> #REF! | D3: =VLOOKUP(B3,#REF!,3,FALSE) -> #REF! | E3: 春日井市
B4: 12 | C4: =VLOOKUP(B4,#REF!,2,FALSE) -> #REF! | D4: =VLOOKUP(B4,#REF!,3,FALSE) -> #REF! | E4: 小牧市
B5: 15 | C5: =VLOOKUP(B5,#REF!,2,FALSE) -> #REF! | D5: =VLOOKUP(B5,#REF!,3,FALSE) -> #REF! | E5: 小牧市
B6: 21 | C6: =VLOOKUP(B6,#REF!,2,FALSE) -> #REF! | D6: =VLOOKUP(B6,#REF!,3,FALSE) -> #REF! | E6: 名古屋市
B7: 22 | C7: =VLOOKUP(B7,#REF!,2,FALSE) -> #REF! | D7: =VLOOKUP(B7,#REF!,3,FALSE) -> #REF! | E7: 名古屋市
B8: 23 | C8: =VLOOKUP(B8,#REF!,2,FALSE) -> #REF! | D8: =VLOOKUP(B8,#REF!,3,FALSE) -> #REF! | E8: 名古屋市
B9: 24 | C9: =VLOOKUP(B9,#REF!,2,FALSE) -> #REF! | D9: =VLOOKUP(B9,#REF!,3,FALSE) -> #REF! | E9: 名古屋市
B10: 28 | C10: =VLOOKUP(B10,#REF!,2,FALSE) -> #REF! | D10: =VLOOKUP(B10,#REF!,3,FALSE) -> #REF! | E10: 名古屋市
B11: 34 | C11: =VLOOKUP(B11,#REF!,2,FALSE) -> #REF! | D11: =VLOOKUP(B11,#REF!,3,FALSE) -> #REF! | E11: 名古屋市
B12: 39 | C12: =VLOOKUP(B12,#REF!,2,FALSE) -> #REF! | D12: =VLOOKUP(B12,#REF!,3,FALSE) -> #REF! | E12: 名古屋市
B13: 40 | C13: =VLOOKUP(B13,#REF!,2,FALSE) -> #REF! | D13: =VLOOKUP(B13,#REF!,3,FALSE) -> #REF! | E13: 名古屋市
... B123: 3025 | C123: =VLOOKUP(B123,#REF!,2,FALSE) -> #REF! | D123: =VLOOKUP(B123,#REF!,3,FALSE) -> #REF! | E123: 豊田市
B124: 3027 | C124: =VLOOKUP(B124,#REF!,2,FALSE) -> #REF! | D124: 大阪府大阪市住之江区南港北1丁目13-11 · | E124: 大阪府大阪市
B125: 3028 | C125: =VLOOKUP(B125,#REF!,2,FALSE) -> #REF! | D125: =VLOOKUP(B125,#REF!,3,FALSE) -> #REF! | E125: 静岡県伊豆市
B126: 3029 | C126: =VLOOKUP(B126,#REF!,2,FALSE) -> #REF! | D126: =VLOOKUP(B126,#REF!,3,FALSE) -> #REF! | E126: 大阪府大阪市
B127: 3030 | C127: =VLOOKUP(B127,#REF!,2,FALSE) -> #REF! | D127: =VLOOKUP(B127,#REF!,3,FALSE) -> #REF! | E127: 東京都江東区
B128: 3031 | C128: =VLOOKUP(B128,#REF!,2,FALSE) -> #REF! | D128: =VLOOKUP(B128,#REF!,3,FALSE) -> #REF! | E128: 岡崎市
B129: 3032 | C129: =VLOOKUP(B129,#REF!,2,FALSE) -> #REF! | D129: =VLOOKUP(B129,#REF!,3,FALSE) -> #REF! | E129: 新城市
B130: 3033 | C130: =VLOOKUP(B130,#REF!,2,FALSE) -> #REF! | D130: =VLOOKUP(B130,#REF!,3,FALSE) -> #REF! | E130: 岐阜県多治見市
B131: 3034 | C131: =VLOOKUP(B131,#REF!,2,FALSE) -> #REF! | D131: =VLOOKUP(B131,#REF!,3,FALSE) -> #REF! | E131: 静岡県浜松市

Sheet 予算管理比較積算 (VIL移管前)
A1: 24/10時点 | B1: 全体予算 | D1: アジア | H1: 一旦計算（非表示） | J1: パラ | N1: 一旦計算（非表示） | P1: 全体
B2: 予算項目 | C2: 予算金額（VIL移管分含む） | D2: 項目 | E2: 単価 | F2: 人数 | G2: 泊数 | I2: 小計 | J2: 項目 | K2: 単価 | L2: 人数 | M2: 泊数 | O2: 小計 | P2: 合計
B3: 客室確保費（朝食付） | C3: 15457292778 | D3: ホテル（選手団） | E3: 3042691395 | F3: 1 | G3: 1 | I3: =E3*F3*G3 -> 3042691395 | J3: ホテル（選手団） | K3: 2596055904 | L3: 1 | M3: 1 | O3: =K3*L3*M3 -> 2596055904 | P3: =I3+O3 -> 5638747299
D4: ホテル（選手団以外） | E4: 7718814575 | F4: 1 | G4: 1 | I4: =E4*F4*G4 -> 7718814575 | J4: ホテル（選手団以外） | K4: 2099730904 | L4: 1 | M4: 1 | O4: =K4*L4*M4 -> 2099730904 | P4: =I4+O4 -> 9818545479
D5: （ファミリーAINAGOC負担） | E5: 2004704909 | F5: 1 | G5: 1 | I5: =E5*F5*G5 -> 2004704909 | J5: （ファミリーAINAGOC負担） | K5: 197828150 | L5: 1 | M5: 1 | O5: =K5*L5*M5 -> 197828150 | P5: =I5+O5 -> 2202533059
D6: （ファミリー利用者負担） | E6: 881565432 | F6: 1 | G6: 1 | I6: =E6*F6*G6 -> 881565432 | J6: （ファミリー利用者負担） | K6: 449927739 | L6: 1 | M6: 1 | O6: =K6*L6*M6 -> 449927739 | P6: =I6+O6 -> 1331493171
D7: （技術役員） | E7: 723774664 | F7: 1 | G7: 1 | I7: =E7*F7*G7 -> 723774664 | J7: （技術役員） | K7: 217404288 | L7: 1 | M7: 1 | O7: =K7*L7*M7 -> 217404288 | P7: =I7+O7 -> 941178952
D8: （スポンサー利用者負担） | E8: =SUM('財政見通し積算 (全SH全項目統合版）'!AD29) -> 2342187094 | F8: 1 | G8: 1 | I8: =E8*F8*G8 -> 2342187094 | J8: （スポンサー利用者負担） | K8: 783186617 | L8: 1 | M8: 1 | O8: =K8*L8*M8 -> 783186617 | P8: =I8+O8 -> 3125373711
D9: （メディア利用者負担） | E9: =SUM('財政見通し積算 (全SH全項目統合版）'!AD30) -> 1766582476 | F9: 1 | G9: 1 | I9: =E9*F9*G9 -> 1766582476 | J9: （メディア利用者負担） | K9: =SUM('財政見通し積算 (全SH全項目統合版）'!AD35) -> 451384110 | L9: 1 | M9: 1 | O9: =K9*L9*M9 -> 451384110 | P9: =I9+O9 -> 2217966586
B10: 飲食費（昼食及び夕食） | C10: 2004611332 | D10: ホテル（選手団） | E10: 16900 | F10: 3546 | G10: 11 | H10: =F10*G10 -> 39006 | I10: =E10*F10*G10 -> 659201400 | J10: ホテル（選手団） | K10: 16900 | L10: =3305*0.6 -> 1983 | M10: 13 | N10: =L10*M10 -> 25779 | O10: =K10*L10*M10 -> 435665100 | P10: =I10+O10 -> 1094866500
D11: ホテル（選手団以外） | E11: =SUM(E12:E13) -> 487471732 | F11: 1 | G11: 1 | I11: =E11*F11*G11 -> 487471732 | J11: ホテル（選手団以外） | K11: =SUM(K12:K13) -> 77936100 | L11: 1 | M11: 1 | O11: =K11*L11*M11 -> 77936100 | P11: =I11+O11 -> 565407832
D12: （ファミリーAINAGOC負担） | E12: 324285720 | F12: 1 | G12: 1 | I12: =E12*F12*G12 -> 324285720 | J12: （ファミリーAINAGOC負担） | K12: 23802106 | L12: 1 | M12: 1 | O12: =K12*L12*M12 -> 23802106 | P12: =I12+O12 -> 348087826
D13: （ファミリー利用者負担） | E13: 163186012 | F13: 1 | G13: 1 | I13: =E13*F13*G13 -> 163186012 | J13: （ファミリー利用者負担） | K13: 54133994 | L13: 1 | M13: 1 | O13: =K13*L13*M13 -> 54133994 | P13: =I13+O13 -> 217320006
D14: コンテナ | E14: 21000 | F14: 725 | G14: 11 | H14: =F14*G14 -> 7975 | I14: 167496000 | J14: コンテナ（選手団） | K14: 21000 | L14: =695*0.6 -> 417 | M14: 13 | N14: =L14*M14 -> 5421 | O14: =K14*L14*M14 -> 113841000 | P14: =I14+O14 -> 281337000
I15: =E15*F15*G15 -> 0 | J15: コンテナ（NOC本部） | K15: 21000 | L15: 200 | M15: 15 | N15: =L15*M15 -> 3000 | O15: =K15*L15*M15 -> 63000000 | P15: =I15+O15 -> 63000000
B16: 飲食費（ハラル・ヴィーガン対応） | C16: 1354510000 | D16: ホテル | E16: 19000 | F16: 4189 | G16: 11 | H16: =F16*G16 -> 46079 | I16: =E16*F16*G16 -> 875501000 | J16: ホテル | K16: 19000 | L16: =3305*0.4 -> 1322 | M16: 13 | N16: =L16*M16 -> 17186 | O16: =K16*L16*M16 -> 326534000 | P16: =I16+O16 -> 1202035000 | Q16: =P16/2 -> 601017500
D17: コンテナ | E17: 19000 | F17: 401 | G17: 11 | H17: =F17*G17 -> 4411 | I17: =E17*F17*G17 -> 83809000 | J17: コンテナ | K17: 19000 | L17: =695*0.4 -> 278 | M17: 13 | N17: =L17*M17 -> 3614 | O17: =K17*L17*M17 -> 68666000 | P17: =I17+O17 -> 152475000 | Q17: =P17/2 -> 76237500
B18: 飲食費（グラブアンドゴー） | C18: 183440400 | D18: ホテル | E18: 880 | F18: 9235 | G18: 11 | H18: =F18*G18 -> 101585 | I18: =E18*F18*G18 -> 89394800 | J18: ホテル | K18: 880 | L18: 3305 | M18: 13 | N18: =L18*M18 -> 42965 | O18: =K18*L18*M18 -> 37809200 | P18: =I18+O18 -> 127204000
D19: コンテナ | E19: 880 | F19: 1002 | G19: 11 | H19: =F19*G19 -> 11022 | I19: =E19*F19*G19 -> 9699360 | J19: コンテナ | K19: 880 | L19: 695 | M19: 13 | N19: =L19*M19 -> 9035 | O19: =K19*L19*M19 -> 7950800 | P19: =I19+O19 -> 17650160
D20: 船 | E20: 880 | F20: 2436 | G20: 18 | H20: =F20*G20 -> 43848 | I20: =E20*F20*G20 -> 38586240 | O20: =K20*L20*M20 -> 0 | P20: =I20+O20 -> 38586240
B21: 飲食費（アスリートミール：船） | C21: 920808000 | D21: 船 | E21: 21000 | F21: 2436 | G21: 18 | H21: =F21*G21 -> 43848 | I21: =E21*F21*G21 -> 920808000 | O21: =K21*L21*M21 -> 0 | P21: =I21+O21 -> 920808000
B22: 飲食費（空港島運営及びガーデンふ頭運営及び仮設厨房）内容については別紙参照 | C22: 2411358140 | D22: 空港島運営経費 | E22: 1336000000 | F22: 1 | G22: 1 | I22: =E22*F22*G22 -> 1336000000 | P22: =I22+O22 -> 1336000000
D23: 空港島仮設厨房経費 | E23: 101358140 | F23: 1 | G23: 1 | I23: =E23*F23*G23 -> 101358140 | O23: =K23*L23*M23 -> 0 | P23: =I23+O23 -> 101358140
D24: ガーデン運営経費 | E24: 408277000 | F24: 1 | G24: 1 | I24: =E24*F24*G24 -> 408277000 | J24: ガーデン運営経費 | K24: 360000000 | L24: 1 | M24: 1 | O24: =K24*L24*M24 -> 360000000 | P24: =I24+O24 -> 768277000
D25: ガーデン仮設厨房経費 | E25: 205723000 | F25: 1 | G25: 1 | I25: =E25*F25*G25 -> 205723000 | O25: =K25*L25*M25 -> 0 | P25: =I25+O25 -> 205723000
B26: 飲食費（その他経費（支援機器設置等）） | C26: 88652020 | D26: ホテル | E26: 6000000 | F26: 12 | G26: 1 | I26: =E26*F26*G26 -> 72000000 | J26: ホテル | K26: 2378860 | L26: 7 | M26: 1 | O26: =K26*L26*M26 -> 16652020 | P26: =I26+O26 -> 88652020
B27: 会議室等確保費 | C27: 3450377147 | D27: ホテル（選手団） | E27: 858587762 | F27: 1 | G27: 1 | I27: =E27*F27*G27 -> 858587762 | J27: ホテル（選手団） | K27: 1030634912 | L27: 1 | M27: 1 | O27: =K27*L27*M27 -> 1030634912 | P27: =I27+O27 -> 1889222674
D28: ホテル（選手団以外）（ファミリー） | E28: 1178445153 | F28: 1 | G28: 1 | I28: =E28*F28*G28 -> 1178445153 | J28: ホテル（選手団以外）（ファミリー） | K28: 382709320 | L28: 1 | M28: 1 | O28: =K28*L28*M28 -> 382709320 | P28: =I28+O28 -> 1561154473
B29: 営業補償費 | C29: 54466667 | D29: ホテル（選手団以外）（ファミリー） | E29: 34400000 | F29: 1 | G29: 1 | I29: =E29*F29*G29 -> 34400000 | J29: ホテル（選手団以外）（ファミリー） | K29: 20066667 | L29: 1 | M29: 1 | O29: =K29*L29*M29 -> 20066667 | P29: =I29+O29 -> 54466667
B30: 合計 | C30: =SUM(C3:C29) -> 25925516484 | I30: =SUM(I3:I4,I10:I11,I14,I16:I17,I18,I19:I20,I21,I22:I25,I26,I27:I28,I29) -> 18288264557 | O30: =SUM(O3:O4,O10:O11,O14:O15,O16:O17,O18,O19,O24,O26,O27:O28,O29) -> 7637251927 | P30: =SUM(P3:P4,P10:P11,P14:P15,P16:P17,P18,P19:P20,P21,P22:P25,P26,P27:P28,P29) -> 25925516484
A33: 25/6時点 | B33: 全体額 | D33: アジア | J33: パラ | P33: 全体
B34: 予算項目 | C34: 予算金額（VIL移管分含む） | D34: 項目 | E34: 単価 | F34: 人数 | G34: 泊数 | I34: 小計 | J34: 項目 | K34: 単価 | L34: 人数 | M34: 泊数 | O34: 小計 | P34: 合計 | Q34: 差し引き（項目ごと） | R34: 差し引き（項目ごと）
B35: 客室確保費（朝食付） | C35: 15457292778 | D35: ホテル（選手団） | E35: ='財政見通し積算 (全SH全項目統合版）'!C26 -> #REF! | F35: 1 | G35: 1 | I35: =E35*F35*G35 -> #REF! | J35: ホテル（選手団） | K35: ='財政見通し積算 (全SH全項目統合版）'!C31 -> #REF! | L35: 1 | M35: 1 | O35: =K35*L35*M35 -> #REF! | P35: =I35+O35 -> #REF! | Q35: =SUM(P35:P36)-C35 -> #REF! | R35: =SUM(P35:P36)-C35 -> #REF!
D36: ホテル（選手団以外） | I36: =SUM(I37:I41) -> 7.8708056e+09 | J36: ホテル（選手団以外） | O36: =SUM(O37:O41) -> 2.0563535e+09 | P36: =SUM(P37:P41) -> 9.9271591e+09
D37: （ファミリーAINAGOC負担） | E37: ='財政見通し積算 (全SH全項目統合版）'!C27 -> 2204156998 | F37: 1 | G37: 1 | I37: =E37*F37*G37 -> 2204156998 | J37: （ファミリーAINAGOC負担） | K37: ='財政見通し積算 (全SH全項目統合版）'!C32-K38 -> 177614008 | L37: 1 | M37: 1 | O37: =K37*L37*M37 -> 177614008 | P37: =I37+O37 -> 2381771006
J38: （ファミリー利用者負担） | K38: =[47]【250327】アジパラファミリー!$BV$28 -> 294503792 | L38: 1 | M38: 1 | O38: =K38*L38*M38 -> 294503792 | P38: =I38+O38 -> 294503792
D39: （技術役員） | E39: ='財政見通し積算 (全SH全項目統合版）'!C28 -> 1724607631 | F39: 1 | G39: 1 | I39: =E39*F39*G39 -> 1724607631 | J39: （技術役員） | K39: ='財政見通し積算 (全SH全項目統合版）'!C33 -> 344907436 | L39: 1 | M39: 1 | O39: =K39*L39*M39 -> 344907436 | P39: =I39+O39 -> 2069515067
D40: （スポンサー利用者負担） | E40: ='財政見通し積算 (全SH全項目統合版）'!C29 -> 1.2854877e+09 | F40: 1 | G40: 1 | I40: =E40*F40*G40 -> 1.2854877e+09 | J40: （スポンサー利用者負担） | K40: ='財政見通し積算 (全SH全項目統合版）'!C34 -> 8.3703864e+08 | L40: 1 | M40: 1 | O40: =K40*L40*M40 -> 8.3703864e+08 | P40: =I40+O40 -> 2.1225263e+09
D41: （メディア利用者負担） | E41: ='財政見通し積算 (全SH全項目統合版）'!C30 -> 2656553304 | F41: 1 | G41: 1 | I41: =E41*F41*G41 -> 2656553304 | J41: （メディア利用者負担） | K41: ='財政見通し積算 (全SH全項目統合版）'!C35 -> 4.022896e+08 | L41: 1 | M41: 1 | O41: =K41*L41*M41 -> 4.022896e+08 | P41: =I41+O41 -> 3.0588429e+09
B42: 飲食費（昼食及び夕食） | C42: 2004611332 | D42: ホテル（選手団）昼食及び夕食 | E42: 16900 | F42: 58451 | G42: 1 | I42: =E42*F42*G42 -> 987821900 | J42: ホテル（選手団）昼食及び夕食 | K42: 16900 | L42: 31699 | M42: 1 | N42: =L42*M42 -> 31699 | O42: =K42*L42*M42 -> 535713100 | P42: =I42+O42 -> 1523535000 | Q42: =SUM(P42:P44,P47)-C42 -> #REF! | R42: =SUM(P42:P47)-C42 -> #REF!
...

Sheet 内示額反映積算（VIL移管反映）
A2: 24/10時点 | B2: 全体予算 | D2: アジア | H2: 一旦計算（非表示） | J2: パラ | N2: 一旦計算（非表示） | P2: 全体
B3: 予算項目 | C3: 予算金額（VIL移管分含む） | D3: 項目 | E3: 単価 | F3: 人数 | G3: 泊数 | I3: 小計 | J3: 項目 | K3: 単価 | L3: 人数 | M3: 泊数 | O3: 小計 | P3: 合計
B4: 客室確保費（朝食付） | C4: =SUM(P4,P5) -> 15457292778 | D4: ホテル（選手団） | E4: 3042691395 | F4: 1 | G4: 1 | I4: =E4*F4*G4 -> 3042691395 | J4: ホテル（選手団） | K4: 2596055904 | L4: 1 | M4: 1 | O4: =K4*L4*M4 -> 2596055904 | P4: =I4+O4 -> 5638747299
D5: ホテル（選手団以外） | E5: 7718814575 | F5: 1 | G5: 1 | I5: =E5*F5*G5 -> 7718814575 | J5: ホテル（選手団以外） | K5: 2099730904 | L5: 1 | M5: 1 | O5: =K5*L5*M5 -> 2099730904 | P5: =I5+O5 -> 9818545479
D6: （ファミリーAINAGOC負担） | E6: 2004704909 | F6: 1 | G6: 1 | I6: =E6*F6*G6 -> 2004704909 | J6: （ファミリーAINAGOC負担） | K6: 197828150 | L6: 1 | M6: 1 | O6: =K6*L6*M6 -> 197828150 | P6: =I6+O6 -> 2202533059
D7: （ファミリー利用者負担） | E7: 881565432 | F7: 1 | G7: 1 | I7: =E7*F7*G7 -> 881565432 | J7: （ファミリー利用者負担） | K7: 449927739 | L7: 1 | M7: 1 | O7: =K7*L7*M7 -> 449927739 | P7: =I7+O7 -> 1331493171
D8: （技術役員） | E8: 723774664 | F8: 1 | G8: 1 | I8: =E8*F8*G8 -> 723774664 | J8: （技術役員） | K8: 217404288 | L8: 1 | M8: 1 | O8: =K8*L8*M8 -> 217404288 | P8: =I8+O8 -> 941178952
D9: （スポンサー利用者負担） | E9: =SUM('財政見通し積算 (全SH全項目統合版）'!AD29) -> 2342187094 | F9: 1 | G9: 1 | I9: =E9*F9*G9 -> 2342187094 | J9: （スポンサー利用者負担） | K9: 783186617 | L9: 1 | M9: 1 | O9: =K9*L9*M9 -> 783186617 | P9: =I9+O9 -> 3125373711
D10: （メディア利用者負担） | E10: =SUM('財政見通し積算 (全SH全項目統合版）'!AD30) -> 1766582476 | F10: 1 | G10: 1 | I10: =E10*F10*G10 -> 1766582476 | J10: （メディア利用者負担） | K10: =SUM('財政見通し積算 (全SH全項目統合版）'!AD35) -> 451384110 | L10: 1 | M10: 1 | O10: =K10*L10*M10 -> 451384110 | P10: =I10+O10 -> 2217966586
B11: 飲食費（昼食及び夕食） | C11: =SUM(P11:P12) -> 1660274332 | D11: ホテル（選手団） | E11: 16900 | F11: 3546 | G11: 11 | H11: =F11*G11 -> 39006 | I11: =E11*F11*G11 -> 659201400 | J11: ホテル（選手団） | K11: 16900 | L11: =3305*0.6 -> 1983 | M11: 13 | N11: =L11*M11 -> 25779 | O11: =K11*L11*M11 -> 435665100 | P11: =I11+O11 -> 1094866500
D12: ホテル（選手団以外） | E12: =SUM(E13:E14) -> 487471732 | F12: 1 | G12: 1 | I12: =E12*F12*G12 -> 487471732 | J12: ホテル（選手団以外） | K12: =SUM(K13:K14) -> 77936100 | L12: 1 | M12: 1 | O12: =K12*L12*M12 -> 77936100 | P12: =I12+O12 -> 565407832
D13: （ファミリーAINAGOC負担） | E13: 324285720 | F13: 1 | G13: 1 | I13: =E13*F13*G13 -> 324285720 | J13: （ファミリーAINAGOC負担） | K13: 23802106 | L13: 1 | M13: 1 | O13: =K13*L13*M13 -> 23802106 | P13: =I13+O13 -> 348087826
D14: （ファミリー利用者負担） | E14: 163186012 | F14: 1 | G14: 1 | I14: =E14*F14*G14 -> 163186012 | J14: （ファミリー利用者負担） | K14: 54133994 | L14: 1 | M14: 1 | O14: =K14*L14*M14 -> 54133994 | P14: =I14+O14 -> 217320006
D15: コンテナ | E15: 21000 | F15: 725 | G15: 11 | H15: =F15*G15 -> 7975 | I15: 167496000 | J15: コンテナ（選手団） | K15: 21000 | L15: =695*0.6 -> 417 | M15: 13 | N15: =L15*M15 -> 5421 | O15: =K15*L15*M15 -> 113841000 | P15: =I15+O15 -> 281337000
I16: =E16*F16*G16 -> 0 | J16: コンテナ（NOC本部） | K16: 21000 | L16: 200 | M16: 15 | N16: =L16*M16 -> 3000 | O16: =K16*L16*M16 -> 63000000 | P16: =I16+O16 -> 63000000
B17: 飲食費（ハラル・ヴィーガン対応） | C17: =SUM(P17) -> 1202035000 | D17: ホテル | E17: 19000 | F17: 4189 | G17: 11 | H17: =F17*G17 -> 46079 | I17: =E17*F17*G17 -> 875501000 | J17: ホテル | K17: 19000 | L17: =3305*0.4 -> 1322 | M17: 13 | N17: =L17*M17 -> 17186 | O17: =K17*L17*M17 -> 326534000 | P17: =I17+O17 -> 1202035000
D18: コンテナ | E18: 19000 | F18: 401 | G18: 11 | H18: =F18*G18 -> 4411 | I18: =E18*F18*G18 -> 83809000 | J18: コンテナ | K18: 19000 | L18: =695*0.4 -> 278 | M18: 13 | N18: =L18*M18 -> 3614 | O18: =K18*L18*M18 -> 68666000 | P18: =I18+O18 -> 152475000
B19: 飲食費（グラブアンドゴー） | C19: =SUM(P19) -> 127204000 | D19: ホテル | E19: 880 | F19: 9235 | G19: 11 | H19: =F19*G19 -> 101585 | I19: =E19*F19*G19 -> 89394800 | J19: ホテル | K19: 880 | L19: 3305 | M19: 13 | N19: =L19*M19 -> 42965 | O19: =K19*L19*M19 -> 37809200 | P19: =I19+O19 -> 127204000
D20: コンテナ | E20: 880 | F20: 1002 | G20: 11 | H20: =F20*G20 -> 11022 | I20: =E20*F20*G20 -> 9699360 | J20: コンテナ | K20: 880 | L20: 695 | M20: 13 | N20: =L20*M20 -> 9035 | O20: =K20*L20*M20 -> 7950800 | P20: =I20+O20 -> 17650160
D21: 船 | E21: 880 | F21: 2436 | G21: 18 | H21: =F21*G21 -> 43848 | I21: =E21*F21*G21 -> 38586240 | O21: =K21*L21*M21 -> 0 | P21: =I21+O21 -> 38586240
B22: 飲食費（アスリートミール：船） | C22: 920808000 | D22: 船 | E22: 21000 | F22: 2436 | G22: 18 | H22: =F22*G22 -> 43848 | I22: =E22*F22*G22 -> 920808000 | O22: =K22*L22*M22 -> 0 | P22: =I22+O22 -> 920808000
B23: 飲食費（空港島運営及びガーデンふ頭運営及び仮設厨房） | C23: =SUM(P23:P24) -> 1437358140 | D23: 空港島運営経費 | E23: 1336000000 | F23: 1 | G23: 1 | I23: =E23*F23*G23 -> 1336000000 | P23: =I23+O23 -> 1336000000
B24: 内容については別紙参照 | D24: 空港島仮設厨房経費 | E24: 101358140 | F24: 1 | G24: 1 | I24: =E24*F24*G24 -> 101358140 | O24: =K24*L24*M24 -> 0 | P24: =I24+O24 -> 101358140
D25: ガーデン運営経費 | E25: 408277000 | F25: 1 | G25: 1 | I25: =E25*F25*G25 -> 408277000 | J25: ガーデン運営経費 | K25: 360000000 | L25: 1 | M25: 1 | O25: =K25*L25*M25 -> 360000000 | P25: =I25+O25 -> 768277000
D26: ガーデン仮設厨房経費 | E26: 205723000 | F26: 1 | G26: 1 | I26: =E26*F26*G26 -> 205723000 | O26: =K26*L26*M26 -> 0 | P26: =I26+O26 -> 205723000
B27: 飲食費（その他経費（支援機器設置等）） | C27: =SUM(P27) -> 88652020 | D27: ホテル | E27: 6000000 | F27: 12 | G27: 1 | I27: =E27*F27*G27 -> 72000000 | J27: ホテル | K27: 2378860 | L27: 7 | M27: 1 | O27: =K27*L27*M27 -> 16652020 | P27: =I27+O27 -> 88652020
B28: 会議室等確保費 | C28: =SUM(P28:P29) -> 3450377147 | D28: ホテル（選手団） | E28: 858587762 | F28: 1 | G28: 1 | I28: =E28*F28*G28 -> 858587762 | J28: ホテル（選手団） | K28: 1030634912 | L28: 1 | M28: 1 | O28: =K28*L28*M28 -> 1030634912 | P28: =I28+O28 -> 1889222674
D29: ホテル（選手団以外）（ファミリー） | E29: 1178445153 | F29: 1 | G29: 1 | I29: =E29*F29*G29 -> 1178445153 | J29: ホテル（選手団以外）（ファミリー） | K29: 382709320 | L29: 1 | M29: 1 | O29: =K29*L29*M29 -> 382709320 | P29: =I29+O29 -> 1561154473
B30: 営業補償費 | C30: =SUM(P30) -> 54466667 | D30: ホテル（選手団以外）（ファミリー） | E30: 34400000 | F30: 1 | G30: 1 | I30: =E30*F30*G30 -> 34400000 | J30: ホテル（選手団以外）（ファミリー） | K30: 20066667 | L30: 1 | M30: 1 | O30: =K30*L30*M30 -> 20066667 | P30: =I30+O30 -> 54466667
B31: 合計 | C31: =SUM(C4,C11,C17,C19,C23,C27,C28,C30) -> 23477660084 | I31: =SUM(I4:I5,I11:I12,I17,I19,I23:I24,I27,I28:I29,I30) -> 16453865957 | O31: =SUM(O4:O5,O11:O12,O17,O19,O27,O28:O29,O30) -> 7023794127 | P31: =SUM(P4:P5,P11:Q12,P17,P19,P23:P24,P27,P28:P29,P30) -> 23477660084
A34: 25/6時点 | B34: 全体額 | D34: アジア | J34: パラ | P34: 全体
B35: 予算項目 | C35: 予算金額（VIL移管分含む） | D35: 項目 | E35: 単価 | F35: 人数 | G35: 泊数 | I35: 小計 | J35: 項目 | K35: 単価 | L35: 人数 | M35: 泊数 | O35: 小計 | P35: 合計 | Q35: 差し引き（項目ごと） | R35: 差し引き（項目ごと）
B36: 客室確保費（朝食付） | C36: =C4 -> 15457292778 | D36: ホテル（選手団） | E36: 3364680671 | F36: 1 | G36: 1 | I36: =E36*F36*G36 -> 3364680671 | J36: ホテル（選手団） | K36: 2615539538 | L36: 1 | M36: 1 | O36: =K36*L36*M36 -> 2615539538 | P36: =I36+O36 -> 5980220209 | Q36: =SUM(P36:P37)-C36 -> 7.7311319e+08 | R36: =SUM(P36:P37)-C36 -> 7.7311319e+08
D37: ホテル（選手団以外） | I37: =SUM(I38:I42) -> 7.8714323e+09 | J37: ホテル（選手団以外） | O37: =SUM(O38:O42) -> 2.3787535e+09 | P37: =SUM(P38:P42) -> 1.0250186e+10
D38: （ファミリーAINAGOC負担） | E38: 2334813782 | F38: 1 | G38: 1 | I38: =E38*F38*G38 -> 2334813782 | J38: （ファミリーAINAGOC負担） | K38: 237817800 | L38: 1 | M38: 1 | O38: =K38*L38*M38 -> 237817800 | P38: =I38+O38 -> 2572631582
J39: （ファミリー利用者負担） | K39: 234300000 | L39: 1 | M39: 1 | O39: =K39*L39*M39 -> 234300000 | P39: =I39+O39 -> 234300000
D40: （技術役員） | E40: 1.7067982e+09 | F40: 1 | G40: 1 | I40: =E40*F40*G40 -> 1.7067982e+09 | J40: （技術役員） | K40: 412159612 | L40: 1 | M40: 1 | O40: =K40*L40*M40 -> 412159612 | P40: =I40+O40 -> 2.1189579e+09
D41: （スポンサー利用者負担） | E41: 1.4860979e+09 | F41: 1 | G41: 1 | I41: =E41*F41*G41 -> 1.4860979e+09 | J41: （スポンサー利用者負担） | K41: 7.99788e+08 | L41: 1 | M41: 1 | O41: =K41*L41*M41 -> 7.99788e+08 | P41: =I41+O41 -> 2.2858859e+09
D42: （メディア利用者負担） | E42: 2.3437223e+09 | F42: 1 | G42: 1 | I42: =E42*F42*G42 -> 2.3437223e+09 | J42: （メディア利用者負担） | K42: 6.9468807e+08 | L42: 1 | M42: 1 | O42: =K42*L42*M42 -> 6.9468807e+08 | P42: =I42+O42 -> 3.0384104e+09
B43: 飲食費（昼食及び夕食） | C43: =C11 -> 1660274332 | D43: ホテル（選手団）昼食及び夕食 | E43: 16900 | F43: 58451 | G43: 1 | I43: =E43*F43*G43 -> 987821900 | J43: ホテル（選手団）昼食及び夕食 | K43: 16900 | L43: 31699 | M43: 1 | N43: =L43*M43 -> 31699 | O43: =K43*L43*M43 -> 535713100 | P43: =I43+O43 -> 1523535000 | Q43: =SUM(P43:P49)-C43 -> 3552291218 | R43: =SUM(P43:P45)-C43 -> 1430946248
...

Sheet 新予算管理比較積算（VIL移管反映）
A2: 24/10時点 | B2: 全体予算 | D2: アジア | H2: 一旦計算（非表示） | J2: パラ | N2: 一旦計算（非表示） | P2: 全体
B3: 予算項目 | C3: 予算金額（VIL移管分含む） | D3: 項目 | E3: 単価 | F3: 人数 | G3: 泊数 | I3: 小計 | J3: 項目 | K3: 単価 | L3: 人数 | M3: 泊数 | O3: 小計 | P3: 合計
B4: 客室確保費（朝食付） | C4: =SUM(P4,P5) -> 15457292778 | D4: ホテル（選手団） | E4: 3042691395 | F4: 1 | G4: 1 | I4: =E4*F4*G4 -> 3042691395 | J4: ホテル（選手団） | K4: 2596055904 | L4: 1 | M4: 1 | O4: =K4*L4*M4 -> 2596055904 | P4: =I4+O4 -> 5638747299
D5: ホテル（選手団以外） | E5: 7718814575 | F5: 1 | G5: 1 | I5: =E5*F5*G5 -> 7718814575 | J5: ホテル（選手団以外） | K5: 2099730904 | L5: 1 | M5: 1 | O5: =K5*L5*M5 -> 2099730904 | P5: =I5+O5 -> 9818545479
D6: （ファミリーAINAGOC負担） | E6: 2004704909 | F6: 1 | G6: 1 | I6: =E6*F6*G6 -> 2004704909 | J6: （ファミリーAINAGOC負担） | K6: 197828150 | L6: 1 | M6: 1 | O6: =K6*L6*M6 -> 197828150 | P6: =I6+O6 -> 2202533059
D7: （ファミリー利用者負担） | E7: 881565432 | F7: 1 | G7: 1 | I7: =E7*F7*G7 -> 881565432 | J7: （ファミリー利用者負担） | K7: 449927739 | L7: 1 | M7: 1 | O7: =K7*L7*M7 -> 449927739 | P7: =I7+O7 -> 1331493171
D8: （技術役員） | E8: 723774664 | F8: 1 | G8: 1 | I8: =E8*F8*G8 -> 723774664 | J8: （技術役員） | K8: 217404288 | L8: 1 | M8: 1 | O8: =K8*L8*M8 -> 217404288 | P8: =I8+O8 -> 941178952
D9: （スポンサー利用者負担） | E9: =SUM('財政見通し積算 (全SH全項目統合版）'!AD29) -> 2342187094 | F9: 1 | G9: 1 | I9: =E9*F9*G9 -> 2342187094 | J9: （スポンサー利用者負担） | K9: 783186617 | L9: 1 | M9: 1 | O9: =K9*L9*M9 -> 783186617 | P9: =I9+O9 -> 3125373711
D10: （メディア利用者負担） | E10: =SUM('財政見通し積算 (全SH全項目統合版）'!AD30) -> 1766582476 | F10: 1 | G10: 1 | I10: =E10*F10*G10 -> 1766582476 | J10: （メディア利用者負担） | K10: =SUM('財政見通し積算 (全SH全項目統合版）'!AD35) -> 451384110 | L10: 1 | M10: 1 | O10: =K10*L10*M10 -> 451384110 | P10: =I10+O10 -> 2217966586
B11: 飲食費（昼食及び夕食） | C11: =SUM(P11:P12) -> 1660274332 | D11: ホテル（選手団） | E11: 16900 | F11: 3546 | G11: 11 | H11: =F11*G11 -> 39006 | I11: =E11*F11*G11 -> 659201400 | J11: ホテル（選手団） | K11: 16900 | L11: =3305*0.6 -> 1983 | M11: 13 | N11: =L11*M11 -> 25779 | O11: =K11*L11*M11 -> 435665100 | P11: =I11+O11 -> 1094866500
D12: ホテル（選手団以外） | E12: =SUM(E13:E14) -> 487471732 | F12: 1 | G12: 1 | I12: =E12*F12*G12 -> 487471732 | J12: ホテル（選手団以外） | K12: =SUM(K13:K14) -> 77936100 | L12: 1 | M12: 1 | O12: =K12*L12*M12 -> 77936100 | P12: =I12+O12 -> 565407832
D13: （ファミリーAINAGOC負担） | E13: 324285720 | F13: 1 | G13: 1 | I13: =E13*F13*G13 -> 324285720 | J13: （ファミリーAINAGOC負担） | K13: 23802106 | L13: 1 | M13: 1 | O13: =K13*L13*M13 -> 23802106 | P13: =I13+O13 -> 348087826
D14: （ファミリー利用者負担） | E14: 163186012 | F14: 1 | G14: 1 | I14: =E14*F14*G14 -> 163186012 | J14: （ファミリー利用者負担） | K14: 54133994 | L14: 1 | M14: 1 | O14: =K14*L14*M14 -> 54133994 | P14: =I14+O14 -> 217320006
D15: コンテナ | E15: 21000 | F15: 725 | G15: 11 | H15: =F15*G15 -> 7975 | I15: 167496000 | J15: コンテナ（選手団） | K15: 21000 | L15: =695*0.6 -> 417 | M15: 13 | N15: =L15*M15 -> 5421 | O15: =K15*L15*M15 -> 113841000 | P15: =I15+O15 -> 281337000
I16: =E16*F16*G16 -> 0 | J16: コンテナ（NOC本部） | K16: 21000 | L16: 200 | M16: 15 | N16: =L16*M16 -> 3000 | O16: =K16*L16*M16 -> 63000000 | P16: =I16+O16 -> 63000000
B17: 飲食費（ハラル・ヴィーガン対応） | C17: =SUM(P17) -> 1202035000 | D17: ホテル | E17: 19000 | F17: 4189 | G17: 11 | H17: =F17*G17 -> 46079 | I17: =E17*F17*G17 -> 875501000 | J17: ホテル | K17: 19000 | L17: =3305*0.4 -> 1322 | M17: 13 | N17: =L17*M17 -> 17186 | O17: =K17*L17*M17 -> 326534000 | P17: =I17+O17 -> 1202035000
D18: コンテナ | E18: 19000 | F18: 401 | G18: 11 | H18: =F18*G18 -> 4411 | I18: =E18*F18*G18 -> 83809000 | J18: コンテナ | K18: 19000 | L18: =695*0.4 -> 278 | M18: 13 | N18: =L18*M18 -> 3614 | O18: =K18*L18*M18 -> 68666000 | P18: =I18+O18 -> 152475000
B19: 飲食費（グラブアンドゴー） | C19: =SUM(P19) -> 127204000 | D19: ホテル | E19: 880 | F19: 9235 | G19: 11 | H19: =F19*G19 -> 101585 | I19: =E19*F19*G19 -> 89394800 | J19: ホテル | K19: 880 | L19: 3305 | M19: 13 | N19: =L19*M19 -> 42965 | O19: =K19*L19*M19 -> 37809200 | P19: =I19+O19 -> 127204000
D20: コンテナ | E20: 880 | F20: 1002 | G20: 11 | H20: =F20*G20 -> 11022 | I20: =E20*F20*G20 -> 9699360 | J20: コンテナ | K20: 880 | L20: 695 | M20: 13 | N20: =L20*M20 -> 9035 | O20: =K20*L20*M20 -> 7950800 | P20: =I20+O20 -> 17650160
D21: 船 | E21: 880 | F21: 2436 | G21: 18 | H21: =F21*G21 -> 43848 | I21: =E21*F21*G21 -> 38586240 | O21: =K21*L21*M21 -> 0 | P21: =I21+O21 -> 38586240
B22: 飲食費（アスリートミール：船） | C22: 920808000 | D22: 船 | E22: 21000 | F22: 2436 | G22: 18 | H22: =F22*G22 -> 43848 | I22: =E22*F22*G22 -> 920808000 | O22: =K22*L22*M22 -> 0 | P22: =I22+O22 -> 920808000
B23: 飲食費（空港島運営及びガーデンふ頭運営及び仮設厨房） | C23: =SUM(P23:P24) -> 1437358140 | D23: 空港島運営経費 | E23: 1336000000 | F23: 1 | G23: 1 | I23: =E23*F23*G23 -> 1336000000 | P23: =I23+O23 -> 1336000000
B24: 内容については別紙参照 | D24: 空港島仮設厨房経費 | E24: 101358140 | F24: 1 | G24: 1 | I24: =E24*F24*G24 -> 101358140 | O24: =K24*L24*M24 -> 0 | P24: =I24+O24 -> 101358140
D25: ガーデン運営経費 | E25: 408277000 | F25: 1 | G25: 1 | I25: =E25*F25*G25 -> 408277000 | J25: ガーデン運営経費 | K25: 360000000 | L25: 1 | M25: 1 | O25: =K25*L25*M25 -> 360000000 | P25: =I25+O25 -> 768277000
D26: ガーデン仮設厨房経費 | E26: 205723000 | F26: 1 | G26: 1 | I26: =E26*F26*G26 -> 205723000 | O26: =K26*L26*M26 -> 0 | P26: =I26+O26 -> 205723000
B27: 飲食費（その他経費（支援機器設置等）） | C27: =SUM(P27) -> 88652020 | D27: ホテル | E27: 6000000 | F27: 12 | G27: 1 | I27: =E27*F27*G27 -> 72000000 | J27: ホテル | K27: 2378860 | L27: 7 | M27: 1 | O27: =K27*L27*M27 -> 16652020 | P27: =I27+O27 -> 88652020
B28: 会議室等確保費 | C28: =SUM(P28:P29) -> 3450377147 | D28: ホテル（選手団） | E28: 858587762 | F28: 1 | G28: 1 | I28: =E28*F28*G28 -> 858587762 | J28: ホテル（選手団） | K28: 1030634912 | L28: 1 | M28: 1 | O28: =K28*L28*M28 -> 1030634912 | P28: =I28+O28 -> 1889222674
D29: ホテル（選手団以外）（ファミリー） | E29: 1178445153 | F29: 1 | G29: 1 | I29: =E29*F29*G29 -> 1178445153 | J29: ホテル（選手団以外）（ファミリー） | K29: 382709320 | L29: 1 | M29: 1 | O29: =K29*L29*M29 -> 382709320 | P29: =I29+O29 -> 1561154473
B30: 営業補償費 | C30: =SUM(P30) -> 54466667 | D30: ホテル（選手団以外）（ファミリー） | E30: 34400000 | F30: 1 | G30: 1 | I30: =E30*F30*G30 -> 34400000 | J30: ホテル（選手団以外）（ファミリー） | K30: 20066667 | L30: 1 | M30: 1 | O30: =K30*L30*M30 -> 20066667 | P30: =I30+O30 -> 54466667
B31: 合計 | C31: =SUM(C4,C11,C17,C19,C23,C27,C28,C30) -> 23477660084 | I31: =SUM(I4:I5,I11:I12,I17,I19,I23:I24,I27,I28:I29,I30) -> 16453865957 | O31: =SUM(O4:O5,O11:O12,O17,O19,O27,O28:O29,O30) -> 7023794127 | P31: =SUM(P4:P5,P11:Q12,P17,P19,P23:P24,P27,P28:P29,P30) -> 23477660084
A34: 25/6時点 | B34: 全体額 | D34: アジア | J34: パラ | P34: 全体
B35: 予算項目 | C35: 予算金額（VIL移管分含む） | D35: 項目 | E35: 単価 | F35: 人数 | G35: 泊数 | I35: 小計 | J35: 項目 | K35: 単価 | L35: 人数 | M35: 泊数 | O35: 小計 | P35: 合計 | Q35: 差し引き（項目ごと） | R35: 差し引き（項目ごと）
B36: 客室確保費（朝食付） | C36: =C4 -> 15457292778 | D36: ホテル（選手団） | E36: 3364680671 | F36: 1 | G36: 1 | I36: =E36*F36*G36 -> 3364680671 | J36: ホテル（選手団） | K36: 2615539538 | L36: 1 | M36: 1 | O36: =K36*L36*M36 -> 2615539538 | P36: =I36+O36 -> 5980220209 | Q36: =SUM(P36:P37)-C36 -> 7.7311319e+08 | R36: =SUM(P36:P37)-C36 -> 7.7311319e+08
D37: ホテル（選手団以外） | I37: =SUM(I38:I42) -> 7.8714323e+09 | J37: ホテル（選手団以外） | O37: =SUM(O38:O42) -> 2.3787535e+09 | P37: =SUM(P38:P42) -> 1.0250186e+10
D38: （ファミリーAINAGOC負担） | E38: 2334813782 | F38: 1 | G38: 1 | I38: =E38*F38*G38 -> 2334813782 | J38: （ファミリーAINAGOC負担） | K38: 237817800 | L38: 1 | M38: 1 | O38: =K38*L38*M38 -> 237817800 | P38: =I38+O38 -> 2572631582
J39: （ファミリー利用者負担） | K39: 234300000 | L39: 1 | M39: 1 | O39: =K39*L39*M39 -> 234300000 | P39: =I39+O39 -> 234300000
D40: （技術役員） | E40: 1.7067982e+09 | F40: 1 | G40: 1 | I40: =E40*F40*G40 -> 1.7067982e+09 | J40: （技術役員） | K40: 412159612 | L40: 1 | M40: 1 | O40: =K40*L40*M40 -> 412159612 | P40: =I40+O40 -> 2.1189579e+09
D41: （スポンサー利用者負担） | E41: 1.4860979e+09 | F41: 1 | G41: 1 | I41: =E41*F41*G41 -> 1.4860979e+09 | J41: （スポンサー利用者負担） | K41: 7.99788e+08 | L41: 1 | M41: 1 | O41: =K41*L41*M41 -> 7.99788e+08 | P41: =I41+O41 -> 2.2858859e+09
D42: （メディア利用者負担） | E42: 2.3437223e+09 | F42: 1 | G42: 1 | I42: =E42*F42*G42 -> 2.3437223e+09 | J42: （メディア利用者負担） | K42: 6.9468807e+08 | L42: 1 | M42: 1 | O42: =K42*L42*M42 -> 6.9468807e+08 | P42: =I42+O42 -> 3.0384104e+09
B43: 飲食費（昼食及び夕食） | C43: =C11 -> 1660274332 | D43: ホテル（選手団）昼食及び夕食 | E43: 16900 | F43: 58451 | G43: 1 | I43: =E43*F43*G43 -> 987821900 | J43: ホテル（選手団）昼食及び夕食 | K43: 16900 | L43: 31699 | M43: 1 | N43: =L43*M43 -> 31699 | O43: =K43*L43*M43 -> 535713100 | P43: =I43+O43 -> 1523535000 | Q43: =SUM(P43:P49)-C43 -> 3552291218 | R43: =SUM(P43:P45)-C43 -> 1430946248
...

Sheet 予算管理比較積算（VIL移管反映）
A1: 24/10時点 | B1: 全体予算 | D1: アジア | H1: 一旦計算（非表示） | J1: パラ | N1: 一旦計算（非表示） | P1: 全体
B2: 予算項目 | C2: 予算金額（VIL移管分含む） | D2: 項目 | E2: 単価 | F2: 人数 | G2: 泊数 | I2: 小計 | J2: 項目 | K2: 単価 | L2: 人数 | M2: 泊数 | O2: 小計 | P2: 合計
B3: 客室確保費（朝食付） | C3: =SUM(P3,P4) -> 15457292778 | D3: ホテル（選手団） | E3: 3042691395 | F3: 1 | G3: 1 | I3: =E3*F3*G3 -> 3042691395 | J3: ホテル（選手団） | K3: 2596055904 | L3: 1 | M3: 1 | O3: =K3*L3*M3 -> 2596055904 | P3: =I3+O3 -> 5638747299
D4: ホテル（選手団以外） | E4: 7718814575 | F4: 1 | G4: 1 | I4: =E4*F4*G4 -> 7718814575 | J4: ホテル（選手団以外） | K4: 2099730904 | L4: 1 | M4: 1 | O4: =K4*L4*M4 -> 2099730904 | P4: =I4+O4 -> 9818545479
D5: （ファミリーAINAGOC負担） | E5: 2004704909 | F5: 1 | G5: 1 | I5: =E5*F5*G5 -> 2004704909 | J5: （ファミリーAINAGOC負担） | K5: 197828150 | L5: 1 | M5: 1 | O5: =K5*L5*M5 -> 197828150 | P5: =I5+O5 -> 2202533059
D6: （ファミリー利用者負担） | E6: 881565432 | F6: 1 | G6: 1 | I6: =E6*F6*G6 -> 881565432 | J6: （ファミリー利用者負担） | K6: 449927739 | L6: 1 | M6: 1 | O6: =K6*L6*M6 -> 449927739 | P6: =I6+O6 -> 1331493171
D7: （技術役員） | E7: 723774664 | F7: 1 | G7: 1 | I7: =E7*F7*G7 -> 723774664 | J7: （技術役員） | K7: 217404288 | L7: 1 | M7: 1 | O7: =K7*L7*M7 -> 217404288 | P7: =I7+O7 -> 941178952
D8: （スポンサー利用者負担） | E8: =SUM('財政見通し積算 (全SH全項目統合版）'!AD29) -> 2342187094 | F8: 1 | G8: 1 | I8: =E8*F8*G8 -> 2342187094 | J8: （スポンサー利用者負担） | K8: 783186617 | L8: 1 | M8: 1 | O8: =K8*L8*M8 -> 783186617 | P8: =I8+O8 -> 3125373711
D9: （メディア利用者負担） | E9: =SUM('財政見通し積算 (全SH全項目統合版）'!AD30) -> 1766582476 | F9: 1 | G9: 1 | I9: =E9*F9*G9 -> 1766582476 | J9: （メディア利用者負担） | K9: =SUM('財政見通し積算 (全SH全項目統合版）'!AD35) -> 451384110 | L9: 1 | M9: 1 | O9: =K9*L9*M9 -> 451384110 | P9: =I9+O9 -> 2217966586
B10: 飲食費（昼食及び夕食） | C10: =SUM(P10:P11) -> 1660274332 | D10: ホテル（選手団） | E10: 16900 | F10: 3546 | G10: 11 | H10: =F10*G10 -> 39006 | I10: =E10*F10*G10 -> 659201400 | J10: ホテル（選手団） | K10: 16900 | L10: =3305*0.6 -> 1983 | M10: 13 | N10: =L10*M10 -> 25779 | O10: =K10*L10*M10 -> 435665100 | P10: =I10+O10 -> 1094866500
D11: ホテル（選手団以外） | E11: =SUM(E12:E13) -> 487471732 | F11: 1 | G11: 1 | I11: =E11*F11*G11 -> 487471732 | J11: ホテル（選手団以外） | K11: =SUM(K12:K13) -> 77936100 | L11: 1 | M11: 1 | O11: =K11*L11*M11 -> 77936100 | P11: =I11+O11 -> 565407832
D12: （ファミリーAINAGOC負担） | E12: 324285720 | F12: 1 | G12: 1 | I12: =E12*F12*G12 -> 324285720 | J12: （ファミリーAINAGOC負担） | K12: 23802106 | L12: 1 | M12: 1 | O12: =K12*L12*M12 -> 23802106 | P12: =I12+O12 -> 348087826
D13: （ファミリー利用者負担） | E13: 163186012 | F13: 1 | G13: 1 | I13: =E13*F13*G13 -> 163186012 | J13: （ファミリー利用者負担） | K13: 54133994 | L13: 1 | M13: 1 | O13: =K13*L13*M13 -> 54133994 | P13: =I13+O13 -> 217320006
D14: コンテナ | E14: 21000 | F14: 725 | G14: 11 | H14: =F14*G14 -> 7975 | I14: 167496000 | J14: コンテナ（選手団） | K14: 21000 | L14: =695*0.6 -> 417 | M14: 13 | N14: =L14*M14 -> 5421 | O14: =K14*L14*M14 -> 113841000 | P14: =I14+O14 -> 281337000
I15: =E15*F15*G15 -> 0 | J15: コンテナ（NOC本部） | K15: 21000 | L15: 200 | M15: 15 | N15: =L15*M15 -> 3000 | O15: =K15*L15*M15 -> 63000000 | P15: =I15+O15 -> 63000000
B16: 飲食費（ハラル・ヴィーガン対応） | C16: =SUM(P16) -> 1202035000 | D16: ホテル | E16: 19000 | F16: 4189 | G16: 11 | H16: =F16*G16 -> 46079 | I16: =E16*F16*G16 -> 875501000 | J16: ホテル | K16: 19000 | L16: =3305*0.4 -> 1322 | M16: 13 | N16: =L16*M16 -> 17186 | O16: =K16*L16*M16 -> 326534000 | P16: =I16+O16 -> 1202035000
D17: コンテナ | E17: 19000 | F17: 401 | G17: 11 | H17: =F17*G17 -> 4411 | I17: =E17*F17*G17 -> 83809000 | J17: コンテナ | K17: 19000 | L17: =695*0.4 -> 278 | M17: 13 | N17: =L17*M17 -> 3614 | O17: =K17*L17*M17 -> 68666000 | P17: =I17+O17 -> 152475000
B18: 飲食費（グラブアンドゴー） | C18: =SUM(P18) -> 127204000 | D18: ホテル | E18: 880 | F18: 9235 | G18: 11 | H18: =F18*G18 -> 101585 | I18: =E18*F18*G18 -> 89394800 | J18: ホテル | K18: 880 | L18: 3305 | M18: 13 | N18: =L18*M18 -> 42965 | O18: =K18*L18*M18 -> 37809200 | P18: =I18+O18 -> 127204000
D19: コンテナ | E19: 880 | F19: 1002 | G19: 11 | H19: =F19*G19 -> 11022 | I19: =E19*F19*G19 -> 9699360 | J19: コンテナ | K19: 880 | L19: 695 | M19: 13 | N19: =L19*M19 -> 9035 | O19: =K19*L19*M19 -> 7950800 | P19: =I19+O19 -> 17650160
D20: 船 | E20: 880 | F20: 2436 | G20: 18 | H20: =F20*G20 -> 43848 | I20: =E20*F20*G20 -> 38586240 | O20: =K20*L20*M20 -> 0 | P20: =I20+O20 -> 38586240
B21: 飲食費（アスリートミール：船） | C21: 920808000 | D21: 船 | E21: 21000 | F21: 2436 | G21: 18 | H21: =F21*G21 -> 43848 | I21: =E21*F21*G21 -> 920808000 | O21: =K21*L21*M21 -> 0 | P21: =I21+O21 -> 920808000
B22: 飲食費（空港島運営及びガーデンふ頭運営及び仮設厨房） | C22: =SUM(P22:P23) -> 1437358140 | D22: 空港島運営経費 | E22: 1336000000 | F22: 1 | G22: 1 | I22: =E22*F22*G22 -> 1336000000 | P22: =I22+O22 -> 1336000000
B23: 内容については別紙参照 | D23: 空港島仮設厨房経費 | E23: 101358140 | F23: 1 | G23: 1 | I23: =E23*F23*G23 -> 101358140 | O23: =K23*L23*M23 -> 0 | P23: =I23+O23 -> 101358140
D24: ガーデン運営経費 | E24: 408277000 | F24: 1 | G24: 1 | I24: =E24*F24*G24 -> 408277000 | J24: ガーデン運営経費 | K24: 360000000 | L24: 1 | M24: 1 | O24: =K24*L24*M24 -> 360000000 | P24: =I24+O24 -> 768277000
D25: ガーデン仮設厨房経費 | E25: 205723000 | F25: 1 | G25: 1 | I25: =E25*F25*G25 -> 205723000 | O25: =K25*L25*M25 -> 0 | P25: =I25+O25 -> 205723000
B26: 飲食費（その他経費（支援機器設置等）） | C26: =SUM(P26) -> 88652020 | D26: ホテル | E26: 6000000 | F26: 12 | G26: 1 | I26: =E26*F26*G26 -> 72000000 | J26: ホテル | K26: 2378860 | L26: 7 | M26: 1 | O26: =K26*L26*M26 -> 16652020 | P26: =I26+O26 -> 88652020
B27: 会議室等確保費 | C27: =SUM(P27:P28) -> 3450377147 | D27: ホテル（選手団） | E27: 858587762 | F27: 1 | G27: 1 | I27: =E27*F27*G27 -> 858587762 | J27: ホテル（選手団） | K27: 1030634912 | L27: 1 | M27: 1 | O27: =K27*L27*M27 -> 1030634912 | P27: =I27+O27 -> 1889222674
D28: ホテル（選手団以外）（ファミリー） | E28: 1178445153 | F28: 1 | G28: 1 | I28: =E28*F28*G28 -> 1178445153 | J28: ホテル（選手団以外）（ファミリー） | K28: 382709320 | L28: 1 | M28: 1 | O28: =K28*L28*M28 -> 382709320 | P28: =I28+O28 -> 1561154473
B29: 営業補償費 | C29: =SUM(P29) -> 54466667 | D29: ホテル（選手団以外）（ファミリー） | E29: 34400000 | F29: 1 | G29: 1 | I29: =E29*F29*G29 -> 34400000 | J29: ホテル（選手団以外）（ファミリー） | K29: 20066667 | L29: 1 | M29: 1 | O29: =K29*L29*M29 -> 20066667 | P29: =I29+O29 -> 54466667
B30: 合計 | C30: =SUM(C3,C10,C16,C18,C22,C26,C27,C29) -> 23477660084 | I30: =SUM(I3:I4,I10:I11,I16,I18,I22:I23,I26,I27:I28,I29) -> 16453865957 | O30: =SUM(O3:O4,O10:O11,O16,O18,O26,O27:O28,O29) -> 7023794127 | P30: =SUM(P3:P4,P10:Q11,P16,P18,P22:P23,P26,P27:P28,P29) -> 23477660084
A33: 25/6時点 | B33: 全体額 | D33: アジア | J33: パラ | P33: 全体
B34: 予算項目 | C34: 予算金額（VIL移管分含む） | D34: 項目 | E34: 単価 | F34: 人数 | G34: 泊数 | I34: 小計 | J34: 項目 | K34: 単価 | L34: 人数 | M34: 泊数 | O34: 小計 | P34: 合計 | Q34: 差し引き（項目ごと） | R34: 差し引き（項目ごと）
B35: 客室確保費（朝食付） | C35: =C3 -> 15457292778 | D35: ホテル（選手団） | E35: ='財政見通し積算 (全SH全項目統合版）'!C26 -> #REF! | F35: 1 | G35: 1 | I35: =E35*F35*G35 -> #REF! | J35: ホテル（選手団） | K35: ='財政見通し積算 (全SH全項目統合版）'!C31 -> #REF! | L35: 1 | M35: 1 | O35: =K35*L35*M35 -> #REF! | P35: =I35+O35 -> #REF! | Q35: =SUM(P35:P36)-C35 -> #REF! | R35: =SUM(P35:P36)-C35 -> #REF!
D36: ホテル（選手団以外） | I36: =SUM(I37:I41) -> 7.8708056e+09 | J36: ホテル（選手団以外） | O36: =SUM(O37:O41) -> 2.0563535e+09 | P36: =SUM(P37:P41) -> 9.9271591e+09
D37: （ファミリーAINAGOC負担） | E37: ='財政見通し積算 (全SH全項目統合版）'!C27 -> 2204156998 | F37: 1 | G37: 1 | I37: =E37*F37*G37 -> 2204156998 | J37: （ファミリーAINAGOC負担） | K37: ='財政見通し積算 (全SH全項目統合版）'!C32-K38 -> 237817800 | L37: 1 | M37: 1 | O37: =K37*L37*M37 -> 237817800 | P37: =I37+O37 -> 2441974798
J38: （ファミリー利用者負担） | K38: =【250925】アジパラファミリー積算!BS29 -> 234300000 | L38: 1 | M38: 1 | O38: =K38*L38*M38 -> 234300000 | P38: =I38+O38 -> 234300000
D39: （技術役員） | E39: ='財政見通し積算 (全SH全項目統合版）'!C28 -> 1724607631 | F39: 1 | G39: 1 | I39: =E39*F39*G39 -> 1724607631 | J39: （技術役員） | K39: ='財政見通し積算 (全SH全項目統合版）'!C33 -> 344907436 | L39: 1 | M39: 1 | O39: =K39*L39*M39 -> 344907436 | P39: =I39+O39 -> 2069515067
D40: （スポンサー利用者負担） | E40: ='財政見通し積算 (全SH全項目統合版）'!C29 -> 1.2854877e+09 | F40: 1 | G40: 1 | I40: =E40*F40*G40 -> 1.2854877e+09 | J40: （スポンサー利用者負担） | K40: ='財政見通し積算 (全SH全項目統合版）'!C34 -> 8.3703864e+08 | L40: 1 | M40: 1 | O40: =K40*L40*M40 -> 8.3703864e+08 | P40: =I40+O40 -> 2.1225263e+09
D41: （メディア利用者負担） | E41: ='財政見通し積算 (全SH全項目統合版）'!C30 -> 2656553304 | F41: 1 | G41: 1 | I41: =E41*F41*G41 -> 2656553304 | J41: （メディア利用者負担） | K41: ='財政見通し積算 (全SH全項目統合版）'!C35 -> 4.022896e+08 | L41: 1 | M41: 1 | O41: =K41*L41*M41 -> 4.022896e+08 | P41: =I41+O41 -> 3.0588429e+09
B42: 飲食費（昼食及び夕食） | C42: =C10 -> 1660274332 | D42: ホテル（選手団）昼食及び夕食 | E42: 16900 | F42: 58451 | G42: 1 | I42: =E42*F42*G42 -> 987821900 | J42: ホテル（選手団）昼食及び夕食 | K42: 16900 | L42: 31699 | M42: 1 | N42: =L42*M42 -> 31699 | O42: =K42*L42*M42 -> 535713100 | P42: =I42+O42 -> 1523535000 | Q42: =SUM(P42:P48)-C42 -> #REF! | R42: =SUM(P42:P44)-C42 -> #REF!
...

Sheet 食事単価の考え方
B2: 客室単価＋通常朝食と、アスリートミールの財政見通し上の関係性とこれまでの経緯
B3: 例：客室単価9,000円（税込）＋通常朝食1,500円（税込）の場合
B4: ※ハラルヴィーガン単価については別軸
B6: 基本
C7: 客室単価 | E7: 朝食
C10: 9000円 | E10: 1,500円
B12: 財政見通し時（24年10月）
C13: 客室単価 | E13: 朝食 | F13: アスリートミール単価
F14: 朝食4,100円 | H14: 昼食7,400円 | I14: 夕食9,500円
C16: 9000円 | E16: 1,500円 | H16: 21,000円
B18: 査定
C19: 客室単価 | E19: 朝食 | F19: アスリートミール単価
F20: 二重計上という | H20: 昼食7,400円 | I20: 夕食9,500円
F21: ことで切られる
C22: 9000円 | E22: 1,500円 | H22: 16,900円
B25: 昨年度の立てつけ（現実的には破綻）
C27: 客室単価 | D27: アスリートミール単価
D28: 差額の | E28: 通常朝食 | H28: 昼食7,400円 | I28: 夕食9,500円
D29: 2,600円 | E29: 1,500円
C30: 9,000円-2,600円？？ | D30: 4,100円 | H30: 16,900円
C32: ※ホテルへは、【アスリートミール対応朝食と通常朝食の差額】＋【アスリートミール対応昼食】＋【アスリートミール対応夕食】で16,900円程度で案内
C33: ※反応としては、この金額では対応は出来ないと言われている状況。
B35: 今回
C36: 客室単価 | E36: アスリートミール単価
E37: 通常朝食 | F37: 差額の | H37: 昼食7,400円 | I37: 夕食9,500円
E38: 1,500円 | F38: 2,600円
C39: 9,000円 | E39: 4,100円 | H39: 16,900円

Sheet 債務負担行為積算  (全部盛り) 
A1: 債務負担行為（キャンセル期限前の契約金額ベース）
A2: 宿泊料 | G2: 案3 | K2: ※財政見通しver（キャンセル期限後に実際に支払う金額ベース）
B3: ステークホルダー | C3: 1室あたりの 平均単価 | D3: 室数 ※シミュレーションの客室数 | E3: 契約泊数 | F3: 金額 物価上昇前 （G、H列固定値） | G3: 物価上昇率（宿泊） 2021➡2026 | H3: 金額 物価上昇後 （G、H列固定値） | I3: 総 計 | K3: 【参考値】 金額 物価上昇前 （シミュレーション） | L3: 【参考値】 金額 物価上昇後 （シミュレーション）
A4: アジア | B4: 選手団15,000 | C4: =IF(COUNTIF(Results【技術役員スポンサーメディア積算】!C:C, "選手15000")=0, 0, SUMIF(Results【技術役員スポンサーメディア積算】!C:C, "選手15000", Results【技術役員スポンサーメディア積算】!AA:AA) / COUNTIF(Results【技術役員スポンサーメディア積算】!C:C, "選手15000")) -> 0 | D4: 11937 | E4: 32 | F4: =$E$4*$C$4*$D$4 -> 0 | G4: ='物価（案3）'!$I$10 -> 1.34 | H4: =ROUNDUP($C4*$D4*$E4*$G4,0) -> 0 | I4: =H4 -> 0 | K4: =Results【技術役員スポンサーメディア積算】!BC283 -> 1720770931 | L4: =$K4*$G4 -> 2.305833e+09
B5: 選手団12,000 | C5: =IF(COUNTIF(Results【技術役員スポンサーメディア積算】!D:D, "選手12000")=0, 0, SUMIF(Results【技術役員スポンサーメディア積算】!D:D, "選手12000", Results【技術役員スポンサーメディア積算】!AA:AA) / COUNTIF(Results【技術役員スポンサーメディア積算】!D:D, "選手12000")) -> 0 | D5: 9962 | E5: 32 | F5: =E5*C5*D5 -> 0 | G5: ='物価（案3）'!$I$10 -> 1.34 | H5: =ROUNDUP($C5*$D5*$E5*$G5,0) -> 0 | I5: =H5 -> 0 | J5: 不要？ | K5: =Results【技術役員スポンサーメディア積算】!#REF! -> #REF! | L5: =$K5*$G5 -> #REF!
B6: ファミリー | C6: {=IF(SUMPRODUCT(--(Results【技術役員スポンサーメディア積算】!C:C="ファミリー") + --(Results【技術役員スポンサーメディア積算】!D:D="ファミリー"))=0, 0, SUMIFS(Results【技術役員スポンサーメディア積算】!AA:AA, Results【技術役員スポンサーメディア積算】!C:C, "ファミリー") + SUMIFS(Results【技術役員スポンサーメディア積算】!AA:AA, Results【技術役員スポンサーメディア積算】!D:D, "ファミリー") / SUMPRODUCT(--(Results【技術役員スポンサーメディア積算】!C:C="ファミリー") + --(Results【技術役員スポンサーメディア積算】!D:D="ファミリー")))} -> 0 | D6: 1645 | E6: 32 | F6: =E6*C6*D6 -> 0 | G6: ='物価（案3）'!$I$10 -> 1.34 | H6: =ROUNDUP($C6*$D6*$E6*$G6,0) -> 0 | I6: =SUM(H6:H11) -> 10511814540 | K6: =Results【技術役員スポンサーメディア積算】!BD283 -> 959319162 | L6: =$K6*$G6 -> 1.2854877e+09
B7: スポンサー | C7: {=IF(SUMPRODUCT(--(Results【技術役員スポンサーメディア積算】!C:C="スポンサー") + --(Results【技術役員スポンサーメディア積算】!D:D="スポンサー"))=0, 0, (SUMIFS(Results【技術役員スポンサーメディア積算】!AA:AA, Results【技術役員スポンサーメディア積算】!C:C, "スポンサー") + SUMIFS(Results【技術役員スポンサーメディア積算】!AA:AA, Results【技術役員スポンサーメディア積算】!D:D, "スポンサー")) / SUMPRODUCT(--(Results【技術役員スポンサーメディア積算】!C:C="スポンサー") + --(Results【技術役員スポンサーメディア積算】!D:D="スポンサー")))} -> 60684.639 | D7: 2560 | E7: 32 | F7: =E7*C7*D7 -> 4.9712856e+09 | G7: ='物価（案3）'!$I$10 -> 1.34 | H7: =ROUNDUP($C7*$D7*$E7*$G7,0) -> 6661522704 | K7: =Results【技術役員スポンサーメディア積算】!#REF! -> #REF! | L7: =$K7*$G7 -> #REF!
B8: NOC本部 | C8: {=IF(SUMPRODUCT(--(Results【技術役員スポンサーメディア積算】!C:C="本部") + --(Results【技術役員スポンサーメディア積算】!D:D="本部"))=0, 0, (SUMIFS(Results【技術役員スポンサーメディア積算】!AA:AA, Results【技術役員スポンサーメディア積算】!C:C, "本部") + SUMIFS(Results【技術役員スポンサーメディア積算】!AA:AA, Results【技術役員スポンサーメディア積算】!D:D, "本部")) / SUMPRODUCT(--(Results【技術役員スポンサーメディア積算】!C:C="本部") + --(Results【技術役員スポンサーメディア積算】!D:D="本部")))} -> 0 | D8: 286 | E8: 36 | F8: =E8*C8*D8 -> 0 | G8: ='物価（案3）'!$I$10 -> 1.34 | H8: =ROUNDUP($C8*$D8*$E8*$G8,0) -> 0 | K8: =Results【技術役員スポンサーメディア積算】!#REF! -> #REF! | L8: =$K8*$G8 -> #REF!
B9: メディア | C9: {=IF(SUMPRODUCT(--(Results【技術役員スポンサーメディア積算】!C:C="メディア") + --(Results【技術役員スポンサーメディア積算】!D:D="メディア"))=0, 0, (SUMIFS(Results【技術役員スポンサーメディア積算】!AA:AA, Results【技術役員スポンサーメディア積算】!C:C, "メディア") + SUMIFS(Results【技術役員スポンサーメディア積算】!AA:AA, Results【技術役員スポンサーメディア積算】!D:D, "メディア")) / SUMPRODUCT(--(Results【技術役員スポンサーメディア積算】!C:C="メディア") + --(Results【技術役員スポンサーメディア積算】!D:D="メディア")))} -> 0 | D9: 3000 | E9: 32 | F9: =E9*C9*D9 -> 0 | G9: ='物価（案3）'!$I$10 -> 1.34 | H9: =ROUNDUP($C9*$D9*$E9*$G9,0) -> 0 | K9: =Results【技術役員スポンサーメディア積算】!BE283 -> 1980375600 | L9: =$K9*$G9 -> 2653703304
B10: 技術役員（競技役員） | C10: {=IF(SUMPRODUCT(--(Results【技術役員スポンサーメディア積算】!C:C="技術役員") + --(Results【技術役員スポンサーメディア積算】!D:D="技術役員"))=0, 0, (SUMIFS(Results【技術役員スポンサーメディア積算】!AA:AA, Results【技術役員スポンサーメディア積算】!C:C, "技術役員") + SUMIFS(Results【技術役員スポンサーメディア積算】!AA:AA, Results【技術役員スポンサーメディア積算】!D:D, "技術役員")) / SUMPRODUCT(--(Results【技術役員スポンサーメディア積算】!C:C="技術役員") + --(Results【技術役員スポンサーメディア積算】!D:D="技術役員")))} -> 26771.692 | D10: 3354 | E10: 32 | F10: =E10*C10*D10 -> 2.8733521e+09 | G10: ='物価（案3）'!$I$10 -> 1.34 | H10: =ROUNDUP($C10*$D10*$E10*$G10,0) -> 3850291836 | K10: =Results【技術役員スポンサーメディア積算】!#REF! -> #REF! | L10: =$K10*$G10 -> #REF!
B11: 技術役員（DCO) | C11: {=IF(SUMPRODUCT(--(Results【技術役員スポンサーメディア積算】!C:C="DCO") + --(Results【技術役員スポンサーメディア積算】!D:D="DCO") + --(Results【技術役員スポンサーメディア積算】!E:E="DCO"))=0, 0, (SUMIFS(Results【技術役員スポンサーメディア積算】!AA:AA, Results【技術役員スポンサーメディア積算】!C:C, "DCO") + SUMIFS(Results【技術役員スポンサーメディア積算】!AA:AA, Results【技術役員スポンサーメディア積算】!D:D, "DCO") + SUMIFS(Results【技術役員スポンサーメディア積算】!AA:AA, Results【技術役員スポンサーメディア積算】!E:E, "DCO")) / SUMPRODUCT(--(Results【技術役員スポンサーメディア積算】!C:C="DCO") + --(Results【技術役員スポンサーメディア積算】!D:D="DCO") + --(Results【技術役員スポンサーメディア積算】!E:E="DCO")))} -> 0 | D11: 504 | E11: 32 | F11: =E11*C11*D11 -> 0 | G11: ='物価（案3）'!$I$10 -> 1.34 | H11: =ROUNDUP($C11*$D11*$E11*$G11,0) -> 0 | K11: =Results【技術役員スポンサーメディア積算】!#REF! -> #REF! | L11: =$K11*$G11 -> #REF!
A12: パラ | B12: 選手団4,000 | C12: {=IF(SUMPRODUCT(--(Results【技術役員スポンサーメディア積算】!F:F="選手") + --(Results【技術役員スポンサーメディア積算】!G:G="選手"))=0, 0, (SUMIFS(Results【技術役員スポンサーメディア積算】!AA:AA, Results【技術役員スポンサーメディア積算】!F:F, "選手") + SUMIFS(Results【技術役員スポンサーメディア積算】!AA:AA, Results【技術役員スポンサーメディア積算】!G:G, "選手")) / SUMPRODUCT(--(Results【技術役員スポンサーメディア積算】!F:F="選手") + --(Results【技術役員スポンサーメディア積算】!G:G="選手")))} -> 0 | D12: 4988 | E12: 18 | F12: =E12*C12*D12 -> 0 | G12: ='物価（案3）'!$I$10 -> 1.34 | H12: =ROUNDUP($C12*$D12*$E12*$G12,0) -> 0 | I12: =H12 -> 0 | K12: =Results【技術役員スポンサーメディア積算】!BF283 -> 344907436 | L12: =$K12*$G12 -> 4.6217596e+08
B13: 選手団3,600 | C13: {=IF(SUMPRODUCT(--(Results【技術役員スポンサーメディア積算】!F:F="選手") + --(Results【技術役員スポンサーメディア積算】!G:G="選手"))=0, 0, (SUMIFS(Results【技術役員スポンサーメディア積算】!AA:AA, Results【技術役員スポンサーメディア積算】!F:F, "選手") + SUMIFS(Results【技術役員スポンサーメディア積算】!AA:AA, Results【技術役員スポンサーメディア積算】!G:G, "選手")) / SUMPRODUCT(--(Results【技術役員スポンサーメディア積算】!F:F="選手") + --(Results【技術役員スポンサーメディア積算】!G:G="選手")))} -> 0 | D13: 4988 | E13: 18 | F13: =E13*C13*D13 -> 0 | G13: ='物価（案3）'!$I$10 -> 1.34 | H13: =ROUNDUP($C13*$D13*$E13*$G13,0) -> 0 | I13: =H13 -> 0 | J13: 不要？ | K13: =Results【技術役員スポンサーメディア積算】!BG283 -> 624655701 | L13: =$K13*$G13 -> 8.3703864e+08
B14: ファミリー | C14: {=IF(SUMPRODUCT(--(Results【技術役員スポンサーメディア積算】!F:F="ファミリー") + --(Results【技術役員スポンサーメディア積算】!G:G="ファミリー"))=0, 0, (SUMIFS(Results【技術役員スポンサーメディア積算】!AA:AA, Results【技術役員スポンサーメディア積算】!F:F, "ファミリー") + SUMIFS(Results【技術役員スポンサーメディア積算】!AA:AA, Results【技術役員スポンサーメディア積算】!G:G, "ファミリー")) / SUMPRODUCT(--(Results【技術役員スポンサーメディア積算】!F:F="ファミリー") + --(Results【技術役員スポンサーメディア積算】!G:G="ファミリー")))} -> 0 | D14: 370 | E14: 18 | F14: =E14*C14*D14 -> 0 | G14: ='物価（案3）'!$I$10 -> 1.34 | H14: =ROUNDUP($C14*$D14*$E14*$G14,0) -> 0 | I14: =SUM(H14:H19) -> 2457049000 | K14: =Results【技術役員スポンサーメディア積算】!BH283 -> 300216120 | L14: =$K14*$G14 -> 4.022896e+08
B15: スポンサー | C15: {=IF(SUMPRODUCT(--(Results【技術役員スポンサーメディア積算】!F:F="スポンサー") + --(Results【技術役員スポンサーメディア積算】!G:G="スポンサー"))=0, 0, (SUMIFS(Results【技術役員スポンサーメディア積算】!AA:AA, Results【技術役員スポンサーメディア積算】!F:F, "スポンサー") + SUMIFS(Results【技術役員スポンサーメディア積算】!AA:AA, Results【技術役員スポンサーメディア積算】!G:G, "スポンサー")) / SUMPRODUCT(--(Results【技術役員スポンサーメディア積算】!F:F="スポンサー") + --(Results【技術役員スポンサーメディア積算】!G:G="スポンサー")))} -> 53371.432 | D15: 1560 | E15: 18 | F15: =E15*C15*D15 -> 1.4986698e+09 | G15: ='物価（案3）'!$I$10 -> 1.34 | H15: =ROUNDUP($C15*$D15*$E15*$G15,0) -> 2008217561 | K15: =Results【技術役員スポンサーメディア積算】!#REF! -> #REF! | L15: =$K15*$G15 -> #REF!
B16: NPC本部 | C16: {=IF(SUMPRODUCT(--(Results【技術役員スポンサーメディア積算】!F:F="本部") + --(Results【技術役員スポンサーメディア積算】!G:G="本部"))=0, 0, (SUMIFS(Results【技術役員スポンサーメディア積算】!AA:AA, Results【技術役員スポンサーメディア積算】!F:F, "本部") + SUMIFS(Results【技術役員スポンサーメディア積算】!AA:AA, Results【技術役員スポンサーメディア積算】!G:G, "本部")) / SUMPRODUCT(--(Results【技術役員スポンサーメディア積算】!F:F="本部") + --(Results【技術役員スポンサーメディア積算】!G:G="本部")))} -> 0 | D16: 116 | E16: 19 | F16: =E16*C16*D16 -> 0 | G16: ='物価（案3）'!$I$10 -> 1.34 | H16: =ROUNDUP($C16*$D16*$E16*$G16,0) -> 0 | K16: =Results【技術役員スポンサーメディア積算】!#REF! -> #REF! | L16: =$K16*$G16 -> #REF!
B17: メディア | C17: {=IF(SUMPRODUCT(--(Results【技術役員スポンサーメディア積算】!F:F="メディア") + --(Results【技術役員スポンサーメディア積算】!G:G="メディア"))=0, 0, (SUMIFS(Results【技術役員スポンサーメディア積算】!AA:AA, Results【技術役員スポンサーメディア積算】!F:F, "メディア") + SUMIFS(Results【技術役員スポンサーメディア積算】!AA:AA, Results【技術役員スポンサーメディア積算】!G:G, "メディア")) / SUMPRODUCT(--(Results【技術役員スポンサーメディア積算】!F:F="メディア") + --(Results【技術役員スポンサーメディア積算】!G:G="メディア")))} -> 0 | D17: 1600 | E17: 18 | F17: =E17*C17*D17 -> 0 | G17: ='物価（案3）'!$I$10 -> 1.34 | H17: =ROUNDUP($C17*$D17*$E17*$G17,0) -> 0 | K17: =Results【技術役員スポンサーメディア積算】!#REF! -> #REF! | L17: =$K17*$G17 -> #REF!
B18: 技術役員（競技役員） | C18: {=IF(SUMPRODUCT(--(Results【技術役員スポンサーメディア積算】!F:F="技術役員") + --(Results【技術役員スポンサーメディア積算】!G:G="技術役員"))=0, 0, (SUMIFS(Results【技術役員スポンサーメディア積算】!AA:AA, Results【技術役員スポンサーメディア積算】!F:F, "技術役員") + SUMIFS(Results【技術役員スポンサーメディア積算】!AA:AA, Results【技術役員スポンサーメディア積算】!G:G, "技術役員")) / SUMPRODUCT(--(Results【技術役員スポンサーメディア積算】!F:F="技術役員") + --(Results【技術役員スポンサーメディア積算】!G:G="技術役員")))} -> 22916.587 | D18: 812 | E18: 18 | F18: =E18*C18*D18 -> 3.3494884e+08 | G18: ='物価（案3）'!$I$10 -> 1.34 | H18: =ROUNDUP($C18*$D18*$E18*$G18,0) -> 448831439 | K18: =Results【技術役員スポンサーメディア積算】!#REF! -> #REF! | L18: =$K18*$G18 -> #REF!
B19: 技術役員（DCO) | C19: {=IF(SUMPRODUCT(--(Results【技術役員スポンサーメディア積算】!F:F="DCO") + --(Results【技術役員スポンサーメディア積算】!G:G="DCO"))=0, 0, (SUMIFS(Results【技術役員スポンサーメディア積算】!AA:AA, Results【技術役員スポンサーメディア積算】!F:F, "DCO") + SUMIFS(Results【技術役員スポンサーメディア積算】!AA:AA, Results【技術役員スポンサーメディア積算】!G:G, "DCO")) / SUMPRODUCT(--(Results【技術役員スポンサーメディア積算】!F:F="DCO") + --(Results【技術役員スポンサーメディア積算】!G:G="DCO")))} -> 0 | D19: 122 | E19: 18 | F19: =E19*C19*D19 -> 0 | G19: ='物価（案3）'!$I$10 -> 1.34 | H19: =ROUNDUP($C19*$D19*$E19*$G19,0) -> 0 | K19: =Results【技術役員スポンサーメディア積算】!#REF! -> #REF! | L19: =$K19*$G19 -> #REF!
A20: 合計 | B20: - | C20: - | D20: - | E20: - | F20: =SUBTOTAL(109,F4:F19) -> 9.6782564e+09 | G20: - | H20: =SUBTOTAL(109,H4:H19) -> 12968863540 | I20: =SUBTOTAL(109,I4:I19) -> 12968863540 | K20: =SUBTOTAL(109,K4:K19) -> #REF! | L20: =SUBTOTAL(109,L4:L19) -> #REF!
A22: FR料
B23: ステークホルダー | C23: 1室あたりの 平均単価 | D23: 部屋数 ※施設保有FR数 | E23: 契約日数 | F23: 金額 物価上昇前 （G、H列固定値） | G23: 物価上昇率（宿泊） 2021➡2026 | H23: 金額 物価上昇後 （G、H列固定値） | I23: 総 計 | K23: 【参考値】 金額 物価上昇前 （シミュレーション） | L23: 【参考値】 金額 物価上昇後 （シミュレーション）
A24: アジア | B24: 選手団 | C24: =IF(COUNTIFS(Results【技術役員スポンサーメディア積算】!C:C, "選手15000", Results【技術役員スポンサーメディア積算】!V:V, ">0")=0, 0, SUMIFS(Results【技術役員スポンサーメディア積算】!V:V, Results【技術役員スポンサーメディア積算】!C:C, "選手15000", Results【技術役員スポンサーメディア積算】!V:V, ">0") / COUNTIFS(Results【技術役員スポンサーメディア積算】!C:C, "選手15000", Results【技術役員スポンサーメディア積算】!V:V, ">0")) -> 0 | D24: =IF(COUNTIF(Results【技術役員スポンサーメディア積算】!C:C, "選手15000")=0, 0, SUMIF(Results【技術役員スポンサーメディア積算】!C:C, "選手15000", Results【技術役員スポンサーメディア積算】!I:I)) -> 0 | E24: =$E4+1 -> 33 | F24: =E24*C24*D24 -> 0 | G24: ='物価（案3）'!$I$10 -> 1.34 | H24: =ROUNDUP($C24*$D24*$E24*$G24,0) -> 0 | I24: =H24 -> 0 | K24: =Results【技術役員スポンサーメディア積算】!BI283 -> 691185467 | L24: =$K24*$G24 -> 9.2618853e+08
B25: ファミリー | C25: =IF(COUNTIFS(Results【技術役員スポンサーメディア積算】!D:D, "ファミリー", Results【技術役員スポンサーメディア積算】!V:V, ">0")=0, 0, SUMIFS(Results【技術役員スポンサーメディア積算】!V:V, Results【技術役員スポンサーメディア積算】!D:D, "ファミリー", Results【技術役員スポンサーメディア積算】!V:V, ">0") / COUNTIFS(Results【技術役員スポンサーメディア積算】!D:D, "ファミリー", Results【技術役員スポンサーメディア積算】!V:V, ">0")) -> 0 | D25: =IF(COUNTIF(Results【技術役員スポンサーメディア積算】!D:D, "ファミリー")=0, 0, SUMIF(Results【技術役員スポンサーメディア積算】!D:D, "ファミリー", Results【技術役員スポンサーメディア積算】!I:I)) -> 0 | E25: =$E6+1 -> 33 | F25: =E25*C25*D25 -> 0 | G25: ='物価（案3）'!$I$10 -> 1.34 | H25: =ROUNDUP($C25*$D25*$E25*$G25,0) -> 0 | I25: =SUM(H25:H27) -> 0 | K25: =Results【技術役員スポンサーメディア積算】!BJ283 -> 1898926146 | L25: =$K25*$G25 -> 2.544561e+09
B26: スポンサー | G26: ='物価（案3）'!$I$10 -> 1.34 | H26: =ROUNDUP($C26*$D26*$E26*$G26,0) -> 0 | L26: =$K26*$G26 -> 0
B27: NOC本部 | C27: {=IF(SUMPRODUCT(--(Results【技術役員スポンサーメディア積算】!C:C="本部") + --(Results【技術役員スポンサーメディア積算】!D:D="本部"))=0, 0, (SUMIFS(Results【技術役員スポンサーメディア積算】!V:V, Results【技術役員スポンサーメディア積算】!C:C, "本部") + SUMIFS(Results【技術役員スポンサーメディア積算】!V:V, Results【技術役員スポンサーメディア積算】!D:D, "本部")) / SUMPRODUCT(--(Results【技術役員スポンサーメディア積算】!C:C="本部") + --(Results【技術役員スポンサーメディア積算】!D:D="本部")))} -> 0 | D27: =IF(AND(COUNTIF(Results【技術役員スポンサーメディア積算】!C:C, "本部")=0, COUNTIF(Results【技術役員スポンサーメディア積算】!D:D, "本部")=0), 0, IFERROR(SUMIF(Results【技術役員スポンサーメディア積算】!C:C, "本部", Results【技術役員スポンサーメディア積算】!I:I), 0) + IFERROR(SUMIF(Results【技術役員スポンサーメディア積算】!D:D, "本部", Results【技術役員スポンサーメディア積算】!I:I), 0)) -> 0 | E27: =$E8+1 -> 37 | F27: =E27*C27*D27 -> 0 | G27: ='物価（案3）'!$I$10 -> 1.34 | H27: =ROUNDUP($C27*$D27*$E27*$G27,0) -> 0 | K27: =Results【技術役員スポンサーメディア積算】!BK283 -> 87385650 | L27: =$K27*$G27 -> 117096771
A28: パラ | B28: 選手団 | C28: =IF(COUNTIFS(Results【技術役員スポンサーメディア積算】!F:F, "選手", Results【技術役員スポンサーメディア積算】!V:V, ">0")=0, 0, SUMIFS(Results【技術役員スポンサーメディア積算】!V:V, Results【技術役員スポンサーメディア積算】!F:F, "選手", Results【技術役員スポンサーメディア積算】!V:V, ">0") / COUNTIFS(Results【技術役員スポンサーメディア積算】!F:F, "選手", Results【技術役員スポンサーメディア積算】!V:V, ">0")) -> 0 | D28: =IF(COUNTIF(Results【技術役員スポンサーメディア積算】!F:F, "選手")=0, 0, IFERROR(SUMIF(Results【技術役員スポンサーメディア積算】!F:F, "選手", Results【技術役員スポンサーメディア積算】!I:I), 0)) -> 0 | E28: =$E12+1 -> 19 | F28: =E28*C28*D28 -> 0 | G28: ='物価（案3）'!$I$10 -> 1.34 | H28: =ROUNDUP($C28*$D28*$E28*$G28,0) -> 0 | I28: =H28 -> 0 | K28: =Results【技術役員スポンサーメディア積算】!BL283 -> 321313565 | L28: =$K28*$G28 -> 4.3056018e+08
B29: ファミリー | C29: {=IF(SUMPRODUCT(--(Results【技術役員スポンサーメディア積算】!F:F="ファミリー") + --(Results【技術役員スポンサーメディア積算】!G:G="ファミリー"))=0, 0, (SUMIFS(Results【技術役員スポンサーメディア積算】!V:V, Results【技術役員スポンサーメディア積算】!F:F, "ファミリー") + SUMIFS(Results【技術役員スポンサーメディア積算】!V:V, Results【技術役員スポンサーメディア積算】!G:G, "ファミリー")) / SUMPRODUCT(--(Results【技術役員スポンサーメディア積算】!F:F="ファミリー") + --(Results【技術役員スポンサーメディア積算】!G:G="ファミリー")))} -> 0 | D29: =IF(COUNTIF(Results【技術役員スポンサーメディア積算】!F:F, "ファミリー")=0, 0, IFERROR(SUMIF(Results【技術役員スポンサーメディア積算】!F:F, "ファミリー", Results【技術役員スポンサーメディア積算】!I:I), 0)) -> 0 | E29: =$E14+1 -> 19 | F29: =E29*C29*D29 -> 0 | G29: ='物価（案3）'!$I$10 -> 1.34 | H29: =ROUNDUP($C29*$D29*$E29*$G29,0) -> 0 | I29: =SUM(H29:H30) -> 0 | K29: =Results【技術役員スポンサーメディア積算】!BN283 -> 0 | L29: =$K29*$G29 -> 0
B30: NPC本部 | C30: {=IF(SUMPRODUCT(--(Results【技術役員スポンサーメディア積算】!F:F="本部") + --(Results【技術役員スポンサーメディア積算】!G:G="本部"))=0, 0, (SUMIFS(Results【技術役員スポンサーメディア積算】!V:V, Results【技術役員スポンサーメディア積算】!F:F, "本部") + SUMIFS(Results【技術役員スポンサーメディア積算】!V:V, Results【技術役員スポンサーメディア積算】!G:G, "本部")) / SUMPRODUCT(--(Results【技術役員スポンサーメディア積算】!F:F="本部") + --(Results【技術役員スポンサーメディア積算】!G:G="本部")))} -> 0 | D30: =IF(COUNTIF(Results【技術役員スポンサーメディア積算】!F:F, "本部")=0, 0, IFERROR(SUMIF(Results【技術役員スポンサーメディア積算】!F:F, "本部", Results【技術役員スポンサーメディア積算】!I:I), 0)) -> 0 | E30: =$E16+1 -> 20 | F30: =E30*C30*D30 -> 0 | G30: ='物価（案3）'!$I$10 -> 1.34 | H30: =ROUNDUP($C30*$D30*$E30*$G30,0) -> 0 | K30: =Results【技術役員スポンサーメディア積算】!#REF! -> #REF! | L30: =$K30*$G30 -> #REF!
A31: 合計 | B31: - | C31: - | D31: - | E31: - | F31: =SUBTOTAL(109,F24:F30) -> 0 | G31: - | H31: =SUBTOTAL(109,H24:H30) -> 0 | I31: =SUBTOTAL(109,I24:I30) -> 0 | K31: =SUBTOTAL(109,K24:K30) -> #REF! | L31: =SUBTOTAL(109,L24:L30) -> #REF!
A32: ※契約泊数及び日数についてシミュレーションが流動的であるため最大利用期間で契約見込、その後精査しキャンセル期限までにキャンセルする。
H34: 宿泊料＋FR料
H35: アジア | I35: =I4+I6+I24+I25 -> 10511814540
H36: パラ | I36: =I12+I14+I28+I29 -> 2457049000
H37: 合計 | I37: =I35+I36 -> 12968863540
A39: 【パラ本部泊数式修正】（泊数減＋パラ4,000一棟借上げ原則ヤメ）ACM財政見通（v4.3c）
A41: 宿泊料 | G41: 案3 | K41: ※財政見通しver（キャンセル期限後に実際に支払う金額ベース）
B42: ステークホルダー | C42: 1室あたりの 平均単価 | D42: 室数 ※シミュレーションの客室数 | E42: 契約泊数 | F42: 金額 物価上昇前 （G、H列固定値） | G42: 物価上昇率（宿泊） 2021➡2026 | H42: 金額 物価上昇後 （G、H列固定値） | I42: 総 計 | K42: 【参考値】 金額 物価上昇前 （シミュレーション） | L42: 【参考値】 金額 物価上昇後 （シミュレーション）
A43: アジア | B43: 選手団15,000 | C43: ='[48]債務負担行為積算 (数式)'!C4 -> 33756.68 | D43: ='[48]債務負担行為積算 (数式)'!D4 -> 11937 | E43: ='[48]債務負担行為積算 (数式)'!E4 -> 32 | F43: ='[48]債務負担行為積算 (数式)'!F4 -> 1.2894512e+10 | G43: ='[48]債務負担行為積算 (数式)'!G4 -> 1.22 | H43: ='[48]債務負担行為積算 (数式)'!H4 -> 15731304246 | I43: ='[48]債務負担行為積算 (数式)'!I4 -> 15731304246 | J43: ='[48]債務負担行為積算 (数式)'!J4 -> 0 | ... L43: ='[48]債務負担行為積算 (数式)'!L4 -> 1.0689792e+10
B44: 選手団12,000 | C44: ='[48]債務負担行為積算 (数式)'!C5 -> 35104.891 | D44: ='[48]債務負担行為積算 (数式)'!D5 -> 9962 | E44: ='[48]債務負担行為積算 (数式)'!E5 -> 32 | F44: ='[48]債務負担行為積算 (数式)'!F5 -> 1.1190878e+10 | G44: ='[48]債務負担行為積算 (数式)'!G5 -> 1.22 | H44: ='[48]債務負担行為積算 (数式)'!H5 -> 13652870698 | I44: ='[48]債務負担行為積算 (数式)'!I5 -> 13652870698 | J44: ='[48]債務負担行為積算 (数式)'!J5 -> 不要？ | ... L44: ='[48]債務負担行為積算 (数式)'!L5 -> 9.5891368e+09
...

Sheet 財政見通し積算
B2: 財政見通し積算にあたっての前提条件
B3: ○積算するにあたっての単価、泊数等は別シート（Results）にて宿泊施設毎に計算
B4: ○選手団は貸切想定（アジアもパラも）のため、選手団の宿泊施設数が同じの場合は同じ額になる
B5: ○ファミリーのOF1は貸切想定、OF2以下は貸切ではない
B6: ○ファンクションルームの積算については、基本選手、ファミリー、本部は（一応）全施設利用想定
B7: ○物価上昇率は、総務省の消費者物価指数（宿泊料：2021→2023で1.22倍）から算出
B9: Resultsシートの説明
B10: ○各宿泊施設で割り振られるSHを記載（C列～G列、被りの関係で列が分かれる）
B11: ○C列～G列のSH毎の、シミュレーション上の利用客室数をX列～AB列に記載
B12: ○C列～G列のSH毎を参照し、それぞれのSHの宿泊施設毎の泊数を拾ってきている（AK列～AU列）
B13: ○各宿泊施設の客室単価は各シートにて積算、その合計を拾っている（S列）
B14: ○S列を各シートの合計客室数（V列）で割って、一室あたりの平均単価を算出（T列）
... B19: ○宿泊施設毎に算出した金額を、SH毎にまとめている
C21: 客室金額合計 | D21: ファンクションルーム金額合計 | E21: 合計（物価上昇考慮前） | F21: 物価上昇率 | G21: 合計（物価上昇考慮後） | H21: 総計
B22: アジア 選手15,000人 | C22: =SUM(Results【技術役員スポンサーメディア積算】!BC283) -> 1720770931 | D22: =SUM(Results【技術役員スポンサーメディア積算】!BI283) -> 691185467 | E22: =SUM(C22:D22) -> 2411956398 | F22: ='物価（案3）'!$I$10 -> 1.34 | G22: =ROUNDUP($E22*$F22,0) -> 3232021574 | H22: =G22 -> 3232021574
B23: アジア 選手12,000人 | C23: =SUM(Results【技術役員スポンサーメディア積算】!#REF!) -> #REF! | D23: =SUM(Results【技術役員スポンサーメディア積算】!#REF!) -> #REF! | E23: =SUM(C23:D23) -> #REF! | F23: ='物価（案3）'!$I$10 -> 1.34 | G23: =ROUNDUP($E23*$F23,0) -> #REF! | H23: =G23 -> #REF!
B24: アジア ファミリー | C24: =SUM(Results【技術役員スポンサーメディア積算】!BD283) -> 959319162 | D24: =SUM(Results【技術役員スポンサーメディア積算】!BJ283) -> 1898926146 | E24: =SUM(C24:D24) -> 2858245308 | F24: ='物価（案3）'!$I$10 -> 1.34 | G24: =ROUNDUP($E24*$F24,0) -> 3830048713 | H24: =SUM(G24:G29) -> #REF!
B25: アジア スポンサー | C25: =SUM(Results【技術役員スポンサーメディア積算】!#REF!) -> #REF! | D25: =SUM(Results【技術役員スポンサーメディア積算】!#REF!) -> #REF! | E25: =SUM(C25:D25) -> #REF! | F25: ='物価（案3）'!$I$10 -> 1.34 | G25: =ROUNDUP($E25*$F25,0) -> #REF!
B26: アジア 本部 | C26: =SUM(Results【技術役員スポンサーメディア積算】!#REF!) -> #REF! | D26: =SUM(Results【技術役員スポンサーメディア積算】!BK283) -> 87385650 | E26: =SUM(C26:D26) -> #REF! | F26: ='物価（案3）'!$I$10 -> 1.34 | G26: =ROUNDUP($E26*$F26,0) -> #REF!
B27: アジア メディア | C27: =SUM(Results【技術役員スポンサーメディア積算】!BE283) -> 1980375600 | D27: 0 | E27: =SUM(C27:D27) -> 1980375600 | F27: ='物価（案3）'!$I$10 -> 1.34 | G27: =ROUNDUP($E27*$F27,0) -> 2653703304
B28: アジア 技術役員 | C28: =SUM(Results【技術役員スポンサーメディア積算】!#REF!) -> #REF! | D28: 0 | E28: =SUM(C28:D28) -> #REF! | F28: ='物価（案3）'!$I$10 -> 1.34 | G28: =ROUNDUP($E28*$F28,0) -> #REF!
B29: アジア DCO | C29: =SUM(Results【技術役員スポンサーメディア積算】!#REF!) -> #REF! | D29: 0 | E29: =SUM(C29:D29) -> #REF! | F29: ='物価（案3）'!$I$10 -> 1.34 | G29: =ROUNDUP($E29*$F29,0) -> #REF!
B30: パラ 選手4,000人 | C30: =SUM(Results【技術役員スポンサーメディア積算】!BF283) -> 344907436 | D30: =SUM(Results【技術役員スポンサーメディア積算】!BL283) -> 321313565 | E30: =SUM(C30:D30) -> 666221001 | F30: ='物価（案3）'!$I$10 -> 1.34 | G30: =ROUNDUP($E30*$F30,0) -> 892736142 | H30: =G30 -> 892736142
B31: パラ 選手3,600人 | C31: =SUM(Results【技術役員スポンサーメディア積算】!BG283) -> 624655701 | D31: =SUM(Results【技術役員スポンサーメディア積算】!BM283) -> 855630459 | E31: =SUM(C31:D31) -> 1480286160 | F31: ='物価（案3）'!$I$10 -> 1.34 | G31: =ROUNDUP($E31*$F31,0) -> 1983583455 | H31: =G31 -> 1983583455
B32: パラファミリー | C32: =SUM(Results【技術役員スポンサーメディア積算】!BH283) -> 300216120 | D32: =SUM(Results【技術役員スポンサーメディア積算】!BN283) -> 0 | E32: =SUM(C32:D32) -> 300216120 | F32: ='物価（案3）'!$I$10 -> 1.34 | G32: =ROUNDUP($E32*$F32,0) -> 402289601 | H32: =SUM(G32:G37) -> #REF!
B33: パラスポンサー | C33: =SUM(Results【技術役員スポンサーメディア積算】!#REF!) -> #REF! | D33: 0 | E33: =SUM(C33:D33) -> #REF! | F33: ='物価（案3）'!$I$10 -> 1.34 | G33: =ROUNDUP($E33*$F33,0) -> #REF!
B34: パラ本部 | C34: =SUM(Results【技術役員スポンサーメディア積算】!#REF!) -> #REF! | D34: =SUM(Results【技術役員スポンサーメディア積算】!#REF!) -> #REF! | E34: =SUM(C34:D34) -> #REF! | F34: ='物価（案3）'!$I$10 -> 1.34 | G34: =ROUNDUP($E34*$F34,0) -> #REF!
B35: パラメディア | C35: =SUM(Results【技術役員スポンサーメディア積算】!#REF!) -> #REF! | D35: 0 | E35: =SUM(C35:D35) -> #REF! | F35: ='物価（案3）'!$I$10 -> 1.34 | G35: =ROUNDUP($E35*$F35,0) -> #REF!
B36: パラ技術役員 | C36: =SUM(Results【技術役員スポンサーメディア積算】!#REF!) -> #REF! | D36: 0 | E36: =SUM(C36:D36) -> #REF! | F36: ='物価（案3）'!$I$10 -> 1.34 | G36: =ROUNDUP($E36*$F36,0) -> #REF!
B37: パラDCO | C37: =SUM(Results【技術役員スポンサーメディア積算】!#REF!) -> #REF! | D37: 0 | E37: =SUM(C37:D37) -> #REF! | F37: ='物価（案3）'!$I$10 -> 1.34 | G37: =ROUNDUP($E37*$F37,0) -> #REF!
B38: 小計 | C38: =SUM(C22:C37) -> #REF! | D38: =SUM(D22:D37) -> #REF! | E38: =SUM(E22:E37) -> #REF! | G38: =SUM(G22:G37) -> #REF! | H38: =SUM(H22:H37) -> #REF!
C40: 客室金額合計 | D40: ファンクションルーム金額合計 | E40: 合計（物価上昇考慮前） | G40: 合計（物価上昇考慮後）
B41: アジア15,000パターン計 | C41: =SUM(C22,C24:C29) -> #REF! | D41: =SUM(D22,D24:D29) -> #REF! | E41: =SUM(E22,E24:E29) -> #REF! | G41: =SUM(G22,G24:G29) -> #REF!
B42: アジア12,000パターン計 | C42: =SUM(C23,C24:C29) -> #REF! | D42: =SUM(D23,D24:D29) -> #REF! | E42: =SUM(E23,E24:E29) -> #REF! | G42: =SUM(G23,G24:G29) -> #REF!
B43: パラ4,000パターン計 | C43: =SUM(C30,C32:C37) -> #REF! | D43: =SUM(D30,D32:D37) -> #REF! | E43: =SUM(E30,E32:E37) -> #REF! | G43: =SUM(G30,G32:G37) -> #REF!
B44: パラ3,600パターン計 | C44: =SUM(C31,C32:C37) -> #REF! | D44: =SUM(D31,D32:D37) -> #REF! | E44: =SUM(E31,E32:E37) -> #REF! | G44: =SUM(G31,G32:G37) -> #REF!

Sheet 債務負担行為積算  (数式)
A1: 債務負担行為（キャンセル期限前の契約金額ベース）
A2: 宿泊料 | G2: 案3 | K2: ※財政見通しver（キャンセル期限後に実際に支払う金額ベース）
